2019-09-18 12:16:26,110 - INFO - __main__ : 45 - Logging enabled
2019-09-18 12:16:26,120 - INFO - __main__ : 470 - *** Running server in insecure mode on port: 50066 ***
2019-09-18 12:18:35,300 - INFO - __main__ : 372 - GetCapabilities
2019-09-18 12:18:35,301 - INFO - __main__ : 395 - Adding to capabilities: Prophet(['adjustments', 'changePoint', 'dateStamp', 'figures', 'forecastLevel', 'forecastPeriod', 'forecastReturnType', 'fourierOrder', 'outliers'])
2019-09-18 12:18:35,302 - INFO - __main__ : 395 - Adding to capabilities: ProphetScript(['dateStamp', 'figures', 'forecastPeriod', 'forecastType'])
2019-09-18 12:21:34,327 - INFO - __main__ : 45 - Logging enabled
2019-09-18 12:21:34,336 - INFO - __main__ : 478 - *** Running server in insecure mode on port: 50066 ***
2019-09-18 12:21:37,114 - INFO - __main__ : 418 - ExecuteFunction (functionId: 0)
2019-09-18 12:21:37,150 - ERROR - _server : 462 - Exception iterating responses: 'float' object cannot be interpreted as an integer
Traceback (most recent call last):
  File "C:\ProgramData\Anaconda3\lib\site-packages\grpc\_server.py", line 452, in _take_response_from_response_iterator
    return next(response_iterator), True
  File "__main__.py", line 311, in _prophet
    m.fit(dataFrame)
  File "C:\ProgramData\Anaconda3\lib\site-packages\fbprophet\forecaster.py", line 1061, in fit
    self.make_all_seasonality_features(history))
  File "C:\ProgramData\Anaconda3\lib\site-packages\fbprophet\forecaster.py", line 734, in make_all_seasonality_features
    name,
  File "C:\ProgramData\Anaconda3\lib\site-packages\fbprophet\forecaster.py", line 426, in make_seasonality_features
    features = cls.fourier_series(dates, period, series_order)
  File "C:\ProgramData\Anaconda3\lib\site-packages\fbprophet\forecaster.py", line 406, in fourier_series
    for i in range(series_order)
TypeError: 'float' object cannot be interpreted as an integer
2019-09-18 12:21:37,154 - INFO - __main__ : 418 - ExecuteFunction (functionId: 0)
2019-09-18 12:21:37,173 - ERROR - _server : 462 - Exception iterating responses: 'float' object cannot be interpreted as an integer
Traceback (most recent call last):
  File "C:\ProgramData\Anaconda3\lib\site-packages\grpc\_server.py", line 452, in _take_response_from_response_iterator
    return next(response_iterator), True
  File "__main__.py", line 311, in _prophet
    m.fit(dataFrame)
  File "C:\ProgramData\Anaconda3\lib\site-packages\fbprophet\forecaster.py", line 1061, in fit
    self.make_all_seasonality_features(history))
  File "C:\ProgramData\Anaconda3\lib\site-packages\fbprophet\forecaster.py", line 734, in make_all_seasonality_features
    name,
  File "C:\ProgramData\Anaconda3\lib\site-packages\fbprophet\forecaster.py", line 426, in make_seasonality_features
    features = cls.fourier_series(dates, period, series_order)
  File "C:\ProgramData\Anaconda3\lib\site-packages\fbprophet\forecaster.py", line 406, in fourier_series
    for i in range(series_order)
TypeError: 'float' object cannot be interpreted as an integer
2019-09-18 12:22:41,431 - INFO - __main__ : 45 - Logging enabled
2019-09-18 12:22:41,439 - INFO - __main__ : 478 - *** Running server in insecure mode on port: 50066 ***
2019-09-18 12:22:44,720 - INFO - __main__ : 418 - ExecuteFunction (functionId: 0)
2019-09-18 12:22:46,829 - ERROR - _server : 462 - Exception iterating responses: "[''] not in index"
Traceback (most recent call last):
  File "C:\ProgramData\Anaconda3\lib\site-packages\grpc\_server.py", line 452, in _take_response_from_response_iterator
    return next(response_iterator), True
  File "__main__.py", line 345, in _prophet
    forecast = forecast[['ds', forecastReturnType]]
  File "C:\ProgramData\Anaconda3\lib\site-packages\pandas\core\frame.py", line 2934, in __getitem__
    raise_missing=True)
  File "C:\ProgramData\Anaconda3\lib\site-packages\pandas\core\indexing.py", line 1354, in _convert_to_indexer
    return self._get_listlike_indexer(obj, axis, **kwargs)[1]
  File "C:\ProgramData\Anaconda3\lib\site-packages\pandas\core\indexing.py", line 1161, in _get_listlike_indexer
    raise_missing=raise_missing)
  File "C:\ProgramData\Anaconda3\lib\site-packages\pandas\core\indexing.py", line 1252, in _validate_read_indexer
    raise KeyError("{} not in index".format(not_found))
KeyError: "[''] not in index"
2019-09-18 12:22:46,837 - INFO - __main__ : 418 - ExecuteFunction (functionId: 0)
2019-09-18 12:22:48,836 - ERROR - _server : 462 - Exception iterating responses: "[''] not in index"
Traceback (most recent call last):
  File "C:\ProgramData\Anaconda3\lib\site-packages\grpc\_server.py", line 452, in _take_response_from_response_iterator
    return next(response_iterator), True
  File "__main__.py", line 345, in _prophet
    forecast = forecast[['ds', forecastReturnType]]
  File "C:\ProgramData\Anaconda3\lib\site-packages\pandas\core\frame.py", line 2934, in __getitem__
    raise_missing=True)
  File "C:\ProgramData\Anaconda3\lib\site-packages\pandas\core\indexing.py", line 1354, in _convert_to_indexer
    return self._get_listlike_indexer(obj, axis, **kwargs)[1]
  File "C:\ProgramData\Anaconda3\lib\site-packages\pandas\core\indexing.py", line 1161, in _get_listlike_indexer
    raise_missing=raise_missing)
  File "C:\ProgramData\Anaconda3\lib\site-packages\pandas\core\indexing.py", line 1252, in _validate_read_indexer
    raise KeyError("{} not in index".format(not_found))
KeyError: "[''] not in index"
2019-09-18 12:23:56,593 - INFO - __main__ : 45 - Logging enabled
2019-09-18 12:23:56,601 - INFO - __main__ : 480 - *** Running server in insecure mode on port: 50066 ***
2019-09-18 12:24:00,351 - INFO - __main__ : 420 - ExecuteFunction (functionId: 0)
2019-09-18 12:24:43,927 - INFO - __main__ : 45 - Logging enabled
2019-09-18 12:24:43,935 - INFO - __main__ : 480 - *** Running server in insecure mode on port: 50066 ***
2019-09-18 12:24:48,337 - INFO - __main__ : 420 - ExecuteFunction (functionId: 0)
2019-09-18 12:28:26,478 - INFO - __main__ : 382 - GetCapabilities
2019-09-18 12:28:26,478 - INFO - __main__ : 405 - Adding to capabilities: Prophet(['adjustments', 'changePoint', 'dateStamp', 'figures', 'forecastLevel', 'forecastPeriod', 'forecastReturnType', 'fourierOrder', 'outliers'])
2019-09-18 12:28:26,481 - INFO - __main__ : 405 - Adding to capabilities: ProphetScript(['dateStamp', 'figures', 'forecastPeriod', 'forecastType'])
2019-09-18 12:28:42,429 - INFO - __main__ : 420 - ExecuteFunction (functionId: 0)
2019-09-18 12:28:59,848 - INFO - __main__ : 45 - Logging enabled
2019-09-18 12:28:59,855 - INFO - __main__ : 478 - *** Running server in insecure mode on port: 50066 ***
2019-09-18 12:29:00,204 - INFO - __main__ : 418 - ExecuteFunction (functionId: 0)
2019-09-18 12:29:02,204 - INFO - __main__ : 418 - ExecuteFunction (functionId: 0)
2019-09-18 12:29:04,284 - ERROR - _server : 462 - Exception iterating responses: "[''] not in index"
Traceback (most recent call last):
  File "C:\ProgramData\Anaconda3\lib\site-packages\grpc\_server.py", line 452, in _take_response_from_response_iterator
    return next(response_iterator), True
  File "__main__.py", line 345, in _prophet
    forecast = forecast[['ds', forecastReturnType]]
  File "C:\ProgramData\Anaconda3\lib\site-packages\pandas\core\frame.py", line 2934, in __getitem__
    raise_missing=True)
  File "C:\ProgramData\Anaconda3\lib\site-packages\pandas\core\indexing.py", line 1354, in _convert_to_indexer
    return self._get_listlike_indexer(obj, axis, **kwargs)[1]
  File "C:\ProgramData\Anaconda3\lib\site-packages\pandas\core\indexing.py", line 1161, in _get_listlike_indexer
    raise_missing=raise_missing)
  File "C:\ProgramData\Anaconda3\lib\site-packages\pandas\core\indexing.py", line 1252, in _validate_read_indexer
    raise KeyError("{} not in index".format(not_found))
KeyError: "[''] not in index"
2019-09-18 12:29:04,289 - INFO - __main__ : 418 - ExecuteFunction (functionId: 0)
2019-09-18 12:29:06,405 - ERROR - _server : 462 - Exception iterating responses: "[''] not in index"
Traceback (most recent call last):
  File "C:\ProgramData\Anaconda3\lib\site-packages\grpc\_server.py", line 452, in _take_response_from_response_iterator
    return next(response_iterator), True
  File "__main__.py", line 345, in _prophet
    forecast = forecast[['ds', forecastReturnType]]
  File "C:\ProgramData\Anaconda3\lib\site-packages\pandas\core\frame.py", line 2934, in __getitem__
    raise_missing=True)
  File "C:\ProgramData\Anaconda3\lib\site-packages\pandas\core\indexing.py", line 1354, in _convert_to_indexer
    return self._get_listlike_indexer(obj, axis, **kwargs)[1]
  File "C:\ProgramData\Anaconda3\lib\site-packages\pandas\core\indexing.py", line 1161, in _get_listlike_indexer
    raise_missing=raise_missing)
  File "C:\ProgramData\Anaconda3\lib\site-packages\pandas\core\indexing.py", line 1252, in _validate_read_indexer
    raise KeyError("{} not in index".format(not_found))
KeyError: "[''] not in index"
2019-09-18 12:31:45,294 - INFO - __main__ : 45 - Logging enabled
2019-09-18 12:31:45,302 - INFO - __main__ : 480 - *** Running server in insecure mode on port: 50066 ***
2019-09-18 12:31:48,913 - INFO - __main__ : 420 - ExecuteFunction (functionId: 0)
2019-09-18 12:34:55,698 - INFO - __main__ : 45 - Logging enabled
2019-09-18 12:34:55,705 - INFO - __main__ : 480 - *** Running server in insecure mode on port: 50066 ***
2019-09-18 12:34:56,047 - INFO - __main__ : 420 - ExecuteFunction (functionId: 0)
2019-09-18 12:34:58,054 - INFO - __main__ : 420 - ExecuteFunction (functionId: 0)
2019-09-18 12:35:45,676 - INFO - __main__ : 382 - GetCapabilities
2019-09-18 12:35:45,677 - INFO - __main__ : 405 - Adding to capabilities: Prophet(['adjustments', 'changePoint', 'dateStamp', 'figures', 'forecastLevel', 'forecastPeriod', 'forecastReturnType', 'fourierOrder', 'outliers'])
2019-09-18 12:35:45,692 - INFO - __main__ : 405 - Adding to capabilities: ProphetScript(['dateStamp', 'figures', 'forecastPeriod', 'forecastType'])
2019-09-18 12:35:55,373 - INFO - __main__ : 420 - ExecuteFunction (functionId: 0)
2019-09-18 12:41:47,549 - INFO - __main__ : 45 - Logging enabled
2019-09-18 12:41:47,557 - INFO - __main__ : 485 - *** Running server in insecure mode on port: 50066 ***
2019-09-18 12:41:55,340 - INFO - __main__ : 387 - GetCapabilities
2019-09-18 12:41:55,341 - INFO - __main__ : 410 - Adding to capabilities: Prophet(['adjustments', 'changePoint', 'dateStamp', 'figures', 'forecastLevel', 'forecastPeriod', 'forecastReturnType', 'fourierOrder', 'outliers'])
2019-09-18 12:41:55,342 - INFO - __main__ : 410 - Adding to capabilities: ProphetScript(['dateStamp', 'figures', 'forecastPeriod', 'forecastType'])
2019-09-18 12:42:43,804 - INFO - __main__ : 425 - ExecuteFunction (functionId: 0)
2019-09-18 12:44:32,387 - INFO - __main__ : 425 - ExecuteFunction (functionId: 0)
2019-09-18 12:45:38,016 - INFO - __main__ : 45 - Logging enabled
2019-09-18 12:45:38,022 - INFO - __main__ : 485 - *** Running server in insecure mode on port: 50066 ***
2019-09-18 12:45:59,064 - INFO - __main__ : 425 - ExecuteFunction (functionId: 0)
2019-09-18 12:46:37,971 - INFO - __main__ : 425 - ExecuteFunction (functionId: 0)
2019-09-18 12:47:04,262 - INFO - __main__ : 425 - ExecuteFunction (functionId: 0)
2019-09-18 12:48:04,151 - INFO - __main__ : 45 - Logging enabled
2019-09-18 12:48:04,158 - INFO - __main__ : 483 - *** Running server in insecure mode on port: 50066 ***
2019-09-18 12:48:04,370 - INFO - __main__ : 423 - ExecuteFunction (functionId: 0)
2019-09-18 12:48:12,326 - INFO - __main__ : 423 - ExecuteFunction (functionId: 0)
2019-09-18 12:48:17,257 - INFO - __main__ : 423 - ExecuteFunction (functionId: 0)
2019-09-18 12:49:30,025 - INFO - __main__ : 423 - ExecuteFunction (functionId: 0)
2019-09-18 12:49:36,002 - INFO - __main__ : 423 - ExecuteFunction (functionId: 0)
2019-09-18 12:49:39,598 - INFO - __main__ : 423 - ExecuteFunction (functionId: 0)
2019-09-18 12:49:43,308 - INFO - __main__ : 423 - ExecuteFunction (functionId: 0)
2019-09-18 12:49:43,321 - ERROR - _server : 462 - Exception iterating responses: need at least one array to concatenate
Traceback (most recent call last):
  File "C:\ProgramData\Anaconda3\lib\site-packages\grpc\_server.py", line 452, in _take_response_from_response_iterator
    return next(response_iterator), True
  File "__main__.py", line 316, in _prophet
    m.fit(dataFrame)
  File "C:\ProgramData\Anaconda3\lib\site-packages\fbprophet\forecaster.py", line 1061, in fit
    self.make_all_seasonality_features(history))
  File "C:\ProgramData\Anaconda3\lib\site-packages\fbprophet\forecaster.py", line 734, in make_all_seasonality_features
    name,
  File "C:\ProgramData\Anaconda3\lib\site-packages\fbprophet\forecaster.py", line 426, in make_seasonality_features
    features = cls.fourier_series(dates, period, series_order)
  File "C:\ProgramData\Anaconda3\lib\site-packages\fbprophet\forecaster.py", line 406, in fourier_series
    for i in range(series_order)
  File "C:\ProgramData\Anaconda3\lib\site-packages\numpy\lib\shape_base.py", line 640, in column_stack
    return _nx.concatenate(arrays, 1)
ValueError: need at least one array to concatenate
2019-09-18 12:49:43,324 - INFO - __main__ : 423 - ExecuteFunction (functionId: 0)
2019-09-18 12:49:43,337 - ERROR - _server : 462 - Exception iterating responses: need at least one array to concatenate
Traceback (most recent call last):
  File "C:\ProgramData\Anaconda3\lib\site-packages\grpc\_server.py", line 452, in _take_response_from_response_iterator
    return next(response_iterator), True
  File "__main__.py", line 316, in _prophet
    m.fit(dataFrame)
  File "C:\ProgramData\Anaconda3\lib\site-packages\fbprophet\forecaster.py", line 1061, in fit
    self.make_all_seasonality_features(history))
  File "C:\ProgramData\Anaconda3\lib\site-packages\fbprophet\forecaster.py", line 734, in make_all_seasonality_features
    name,
  File "C:\ProgramData\Anaconda3\lib\site-packages\fbprophet\forecaster.py", line 426, in make_seasonality_features
    features = cls.fourier_series(dates, period, series_order)
  File "C:\ProgramData\Anaconda3\lib\site-packages\fbprophet\forecaster.py", line 406, in fourier_series
    for i in range(series_order)
  File "C:\ProgramData\Anaconda3\lib\site-packages\numpy\lib\shape_base.py", line 640, in column_stack
    return _nx.concatenate(arrays, 1)
ValueError: need at least one array to concatenate
2019-09-18 12:50:06,375 - INFO - __main__ : 423 - ExecuteFunction (functionId: 0)
2019-09-18 12:50:11,991 - INFO - __main__ : 423 - ExecuteFunction (functionId: 0)
2019-09-18 12:51:03,849 - INFO - __main__ : 423 - ExecuteFunction (functionId: 0)
2019-09-18 12:51:03,850 - INFO - __main__ : 423 - ExecuteFunction (functionId: 0)
2019-09-18 12:51:03,870 - ERROR - _server : 462 - Exception iterating responses: bad operand type for unary -: 'NoneType'
Traceback (most recent call last):
  File "C:\ProgramData\Anaconda3\lib\site-packages\grpc\_server.py", line 452, in _take_response_from_response_iterator
    return next(response_iterator), True
  File "__main__.py", line 288, in _prophet
    dataFrame.drop(dataFrame.tail(forecastPeriods).index, inplace=True)
  File "C:\ProgramData\Anaconda3\lib\site-packages\pandas\core\generic.py", line 4703, in tail
    return self.iloc[-n:]
TypeError: bad operand type for unary -: 'NoneType'
2019-09-18 12:51:11,075 - INFO - __main__ : 423 - ExecuteFunction (functionId: 0)
2019-09-18 12:51:25,359 - INFO - __main__ : 423 - ExecuteFunction (functionId: 0)
2019-09-18 12:51:37,749 - INFO - __main__ : 423 - ExecuteFunction (functionId: 0)
2019-09-18 12:51:55,378 - INFO - __main__ : 423 - ExecuteFunction (functionId: 0)
2019-09-18 12:51:59,674 - INFO - __main__ : 423 - ExecuteFunction (functionId: 0)
2019-09-18 12:52:03,149 - INFO - __main__ : 423 - ExecuteFunction (functionId: 0)
2019-09-18 12:52:07,363 - INFO - __main__ : 423 - ExecuteFunction (functionId: 0)
2019-09-18 12:52:11,199 - INFO - __main__ : 423 - ExecuteFunction (functionId: 0)
2019-09-18 12:52:19,259 - INFO - __main__ : 423 - ExecuteFunction (functionId: 0)
2019-09-18 12:53:41,974 - INFO - __main__ : 423 - ExecuteFunction (functionId: 0)
2019-09-18 13:03:05,024 - INFO - __main__ : 423 - ExecuteFunction (functionId: 0)
2019-09-18 13:03:53,828 - INFO - __main__ : 423 - ExecuteFunction (functionId: 0)
