2018-07-22 12:43:44,441 - INFO - __main__ : 43 - Logging enabled
2018-07-22 12:43:44,476 - INFO - __main__ : 299 - *** Running server in insecure mode on port: 50066 ***
2018-07-22 12:46:13,015 - INFO - __main__ : 43 - Logging enabled
2018-07-22 12:46:13,025 - INFO - __main__ : 300 - *** Running server in insecure mode on port: 50066 ***
2018-07-22 12:48:53,587 - INFO - __main__ : 43 - Logging enabled
2018-07-22 12:48:53,595 - INFO - __main__ : 300 - *** Running server in insecure mode on port: 50066 ***
2018-07-22 12:49:16,195 - INFO - __main__ : 202 - GetCapabilities
2018-07-22 12:49:16,205 - INFO - __main__ : 225 - Adding to capabilities: Prophet(['dateStamp', 'figures', 'forecastPeriod', 'forecastType', 'outliers'])
2018-07-22 12:49:23,108 - INFO - __main__ : 202 - GetCapabilities
2018-07-22 12:49:23,109 - INFO - __main__ : 225 - Adding to capabilities: Prophet(['dateStamp', 'figures', 'forecastPeriod', 'forecastType', 'outliers'])
2018-07-22 12:49:28,464 - INFO - __main__ : 240 - ExecuteFunction (functionId: 0)
2018-07-22 12:49:58,914 - INFO - __main__ : 240 - ExecuteFunction (functionId: 0)
2018-07-22 12:50:41,568 - INFO - __main__ : 43 - Logging enabled
2018-07-22 12:50:41,578 - INFO - __main__ : 300 - *** Running server in insecure mode on port: 50066 ***
2018-07-22 12:50:52,079 - INFO - __main__ : 202 - GetCapabilities
2018-07-22 12:50:52,080 - INFO - __main__ : 225 - Adding to capabilities: Prophet(['dateStamp', 'figures', 'forecastPeriod', 'forecastType', 'outliers'])
2018-07-22 12:51:01,327 - INFO - __main__ : 240 - ExecuteFunction (functionId: 0)
2018-07-22 12:51:05,921 - INFO - __main__ : 240 - ExecuteFunction (functionId: 0)
2018-07-22 12:54:08,878 - INFO - __main__ : 240 - ExecuteFunction (functionId: 0)
2018-07-22 12:54:17,887 - INFO - __main__ : 240 - ExecuteFunction (functionId: 0)
2018-07-22 12:58:24,085 - INFO - __main__ : 240 - ExecuteFunction (functionId: 0)
2018-07-22 12:58:26,667 - INFO - __main__ : 240 - ExecuteFunction (functionId: 0)
2018-07-22 13:00:52,326 - INFO - __main__ : 240 - ExecuteFunction (functionId: 0)
2018-07-22 13:00:56,361 - INFO - __main__ : 240 - ExecuteFunction (functionId: 0)
2018-07-22 13:07:15,415 - INFO - __main__ : 240 - ExecuteFunction (functionId: 0)
2018-07-22 13:07:22,011 - INFO - __main__ : 240 - ExecuteFunction (functionId: 0)
2018-07-22 13:10:07,172 - INFO - __main__ : 240 - ExecuteFunction (functionId: 0)
2018-07-22 13:10:11,257 - INFO - __main__ : 240 - ExecuteFunction (functionId: 0)
2018-07-22 13:10:12,873 - INFO - __main__ : 240 - ExecuteFunction (functionId: 0)
2018-07-22 13:10:22,550 - INFO - __main__ : 240 - ExecuteFunction (functionId: 0)
2018-07-22 13:10:39,149 - INFO - __main__ : 202 - GetCapabilities
2018-07-22 13:10:39,151 - INFO - __main__ : 225 - Adding to capabilities: Prophet(['dateStamp', 'figures', 'forecastPeriod', 'forecastType', 'outliers'])
2018-07-22 13:10:48,852 - INFO - __main__ : 240 - ExecuteFunction (functionId: 0)
2018-07-22 13:10:55,905 - INFO - __main__ : 240 - ExecuteFunction (functionId: 0)
2018-07-22 13:10:57,631 - INFO - __main__ : 240 - ExecuteFunction (functionId: 0)
2018-07-22 13:19:28,437 - INFO - __main__ : 240 - ExecuteFunction (functionId: 0)
2018-07-22 13:19:59,162 - INFO - __main__ : 240 - ExecuteFunction (functionId: 0)
2018-07-22 13:20:32,939 - INFO - __main__ : 240 - ExecuteFunction (functionId: 0)
2018-07-22 13:20:57,213 - INFO - __main__ : 240 - ExecuteFunction (functionId: 0)
2018-07-22 13:21:05,754 - INFO - __main__ : 240 - ExecuteFunction (functionId: 0)
2018-07-22 13:21:09,751 - INFO - __main__ : 240 - ExecuteFunction (functionId: 0)
2018-07-22 13:21:12,389 - INFO - __main__ : 240 - ExecuteFunction (functionId: 0)
2018-07-22 13:21:31,419 - INFO - __main__ : 240 - ExecuteFunction (functionId: 0)
2018-07-22 13:21:34,056 - INFO - __main__ : 240 - ExecuteFunction (functionId: 0)
2018-07-22 13:26:15,026 - INFO - __main__ : 240 - ExecuteFunction (functionId: 0)
2018-07-22 13:26:21,715 - INFO - __main__ : 240 - ExecuteFunction (functionId: 0)
2018-07-22 13:27:34,286 - INFO - __main__ : 240 - ExecuteFunction (functionId: 0)
2018-07-22 13:53:29,821 - INFO - __main__ : 44 - Logging enabled
2018-07-22 13:53:29,832 - INFO - __main__ : 310 - *** Running server in insecure mode on port: 50066 ***
2018-07-22 13:54:13,002 - INFO - __main__ : 250 - ExecuteFunction (functionId: 0)
2018-07-22 13:54:13,005 - ERROR - _server : 411 - Exception iterating responses: list index out of range
Traceback (most recent call last):
  File "C:\Users\ckg\Envs\Prophet\lib\site-packages\grpc\_server.py", line 401, in _take_response_from_response_iterator
    return next(response_iterator), True
  File "__main__.py", line 122, in _prophet
    adjustments = [d.strData for d in row.duals][5]
IndexError: list index out of range
2018-07-22 13:54:13,147 - INFO - __main__ : 250 - ExecuteFunction (functionId: 0)
2018-07-22 13:54:13,176 - ERROR - _server : 411 - Exception iterating responses: list index out of range
Traceback (most recent call last):
  File "C:\Users\ckg\Envs\Prophet\lib\site-packages\grpc\_server.py", line 401, in _take_response_from_response_iterator
    return next(response_iterator), True
  File "__main__.py", line 122, in _prophet
    adjustments = [d.strData for d in row.duals][5]
IndexError: list index out of range
2018-07-22 13:56:57,314 - INFO - __main__ : 44 - Logging enabled
2018-07-22 13:56:57,323 - INFO - __main__ : 310 - *** Running server in insecure mode on port: 50066 ***
2018-07-22 13:57:18,809 - INFO - __main__ : 212 - GetCapabilities
2018-07-22 13:57:18,816 - INFO - __main__ : 235 - Adding to capabilities: Prophet(['adjustments', 'dateStamp', 'figures', 'forecastPeriod', 'forecastType', 'outliers'])
2018-07-22 13:57:22,287 - INFO - __main__ : 250 - ExecuteFunction (functionId: 0)
2018-07-22 13:57:23,527 - ERROR - _server : 411 - Exception iterating responses: Initialization failed.
Traceback (most recent call last):
  File "C:\Users\ckg\Envs\Prophet\lib\site-packages\fbprophet\forecaster.py", line 836, in fit
    dat, init=stan_init, iter=1e4, **kwargs)
  File "C:\Users\ckg\Envs\Prophet\lib\site-packages\pystan\model.py", line 510, in optimizing
    ret, sample = fit._call_sampler(stan_args)
  File "stanfit4anon_model_1988b9d517e3c16daf27a07f09e3de97_2569974802724943130.pyx", line 876, in stanfit4anon_model_1988b9d517e3c16daf27a07f09e3de97_2569974802724943130.StanFit4Model._call_sampler
  File "stanfit4anon_model_1988b9d517e3c16daf27a07f09e3de97_2569974802724943130.pyx", line 401, in stanfit4anon_model_1988b9d517e3c16daf27a07f09e3de97_2569974802724943130._call_sampler
RuntimeError: Initialization failed.

During handling of the above exception, another exception occurred:

Traceback (most recent call last):
  File "C:\Users\ckg\Envs\Prophet\lib\site-packages\grpc\_server.py", line 401, in _take_response_from_response_iterator
    return next(response_iterator), True
  File "__main__.py", line 158, in _prophet
    m.fit(dataFrame)
  File "C:\Users\ckg\Envs\Prophet\lib\site-packages\fbprophet\forecaster.py", line 840, in fit
    **kwargs
  File "C:\Users\ckg\Envs\Prophet\lib\site-packages\pystan\model.py", line 510, in optimizing
    ret, sample = fit._call_sampler(stan_args)
  File "stanfit4anon_model_1988b9d517e3c16daf27a07f09e3de97_2569974802724943130.pyx", line 876, in stanfit4anon_model_1988b9d517e3c16daf27a07f09e3de97_2569974802724943130.StanFit4Model._call_sampler
  File "stanfit4anon_model_1988b9d517e3c16daf27a07f09e3de97_2569974802724943130.pyx", line 401, in stanfit4anon_model_1988b9d517e3c16daf27a07f09e3de97_2569974802724943130._call_sampler
RuntimeError: Initialization failed.
2018-07-22 13:57:23,557 - INFO - __main__ : 250 - ExecuteFunction (functionId: 0)
2018-07-22 13:57:24,751 - ERROR - _server : 411 - Exception iterating responses: Initialization failed.
Traceback (most recent call last):
  File "C:\Users\ckg\Envs\Prophet\lib\site-packages\fbprophet\forecaster.py", line 836, in fit
    dat, init=stan_init, iter=1e4, **kwargs)
  File "C:\Users\ckg\Envs\Prophet\lib\site-packages\pystan\model.py", line 510, in optimizing
    ret, sample = fit._call_sampler(stan_args)
  File "stanfit4anon_model_1988b9d517e3c16daf27a07f09e3de97_2569974802724943130.pyx", line 876, in stanfit4anon_model_1988b9d517e3c16daf27a07f09e3de97_2569974802724943130.StanFit4Model._call_sampler
  File "stanfit4anon_model_1988b9d517e3c16daf27a07f09e3de97_2569974802724943130.pyx", line 401, in stanfit4anon_model_1988b9d517e3c16daf27a07f09e3de97_2569974802724943130._call_sampler
RuntimeError: Initialization failed.

During handling of the above exception, another exception occurred:

Traceback (most recent call last):
  File "C:\Users\ckg\Envs\Prophet\lib\site-packages\grpc\_server.py", line 401, in _take_response_from_response_iterator
    return next(response_iterator), True
  File "__main__.py", line 158, in _prophet
    m.fit(dataFrame)
  File "C:\Users\ckg\Envs\Prophet\lib\site-packages\fbprophet\forecaster.py", line 840, in fit
    **kwargs
  File "C:\Users\ckg\Envs\Prophet\lib\site-packages\pystan\model.py", line 510, in optimizing
    ret, sample = fit._call_sampler(stan_args)
  File "stanfit4anon_model_1988b9d517e3c16daf27a07f09e3de97_2569974802724943130.pyx", line 876, in stanfit4anon_model_1988b9d517e3c16daf27a07f09e3de97_2569974802724943130.StanFit4Model._call_sampler
  File "stanfit4anon_model_1988b9d517e3c16daf27a07f09e3de97_2569974802724943130.pyx", line 401, in stanfit4anon_model_1988b9d517e3c16daf27a07f09e3de97_2569974802724943130._call_sampler
RuntimeError: Initialization failed.
2018-07-22 14:00:06,077 - INFO - __main__ : 250 - ExecuteFunction (functionId: 0)
2018-07-22 14:00:16,630 - ERROR - _server : 411 - Exception iterating responses: Initialization failed.
Traceback (most recent call last):
  File "C:\Users\ckg\Envs\Prophet\lib\site-packages\fbprophet\forecaster.py", line 836, in fit
    dat, init=stan_init, iter=1e4, **kwargs)
  File "C:\Users\ckg\Envs\Prophet\lib\site-packages\pystan\model.py", line 510, in optimizing
    ret, sample = fit._call_sampler(stan_args)
  File "stanfit4anon_model_1988b9d517e3c16daf27a07f09e3de97_2569974802724943130.pyx", line 876, in stanfit4anon_model_1988b9d517e3c16daf27a07f09e3de97_2569974802724943130.StanFit4Model._call_sampler
  File "stanfit4anon_model_1988b9d517e3c16daf27a07f09e3de97_2569974802724943130.pyx", line 401, in stanfit4anon_model_1988b9d517e3c16daf27a07f09e3de97_2569974802724943130._call_sampler
RuntimeError: Initialization failed.

During handling of the above exception, another exception occurred:

Traceback (most recent call last):
  File "C:\Users\ckg\Envs\Prophet\lib\site-packages\grpc\_server.py", line 401, in _take_response_from_response_iterator
    return next(response_iterator), True
  File "__main__.py", line 158, in _prophet
    # fit data to prophet
  File "C:\Users\ckg\Envs\Prophet\lib\site-packages\fbprophet\forecaster.py", line 840, in fit
    **kwargs
  File "C:\Users\ckg\Envs\Prophet\lib\site-packages\pystan\model.py", line 510, in optimizing
    ret, sample = fit._call_sampler(stan_args)
  File "stanfit4anon_model_1988b9d517e3c16daf27a07f09e3de97_2569974802724943130.pyx", line 876, in stanfit4anon_model_1988b9d517e3c16daf27a07f09e3de97_2569974802724943130.StanFit4Model._call_sampler
  File "stanfit4anon_model_1988b9d517e3c16daf27a07f09e3de97_2569974802724943130.pyx", line 401, in stanfit4anon_model_1988b9d517e3c16daf27a07f09e3de97_2569974802724943130._call_sampler
RuntimeError: Initialization failed.
2018-07-22 14:00:19,329 - INFO - __main__ : 250 - ExecuteFunction (functionId: 0)
2018-07-22 14:00:21,349 - ERROR - _server : 411 - Exception iterating responses: Initialization failed.
Traceback (most recent call last):
  File "C:\Users\ckg\Envs\Prophet\lib\site-packages\fbprophet\forecaster.py", line 836, in fit
    dat, init=stan_init, iter=1e4, **kwargs)
  File "C:\Users\ckg\Envs\Prophet\lib\site-packages\pystan\model.py", line 510, in optimizing
    ret, sample = fit._call_sampler(stan_args)
  File "stanfit4anon_model_1988b9d517e3c16daf27a07f09e3de97_2569974802724943130.pyx", line 876, in stanfit4anon_model_1988b9d517e3c16daf27a07f09e3de97_2569974802724943130.StanFit4Model._call_sampler
  File "stanfit4anon_model_1988b9d517e3c16daf27a07f09e3de97_2569974802724943130.pyx", line 401, in stanfit4anon_model_1988b9d517e3c16daf27a07f09e3de97_2569974802724943130._call_sampler
RuntimeError: Initialization failed.

During handling of the above exception, another exception occurred:

Traceback (most recent call last):
  File "C:\Users\ckg\Envs\Prophet\lib\site-packages\grpc\_server.py", line 401, in _take_response_from_response_iterator
    return next(response_iterator), True
  File "__main__.py", line 158, in _prophet
    # fit data to prophet
  File "C:\Users\ckg\Envs\Prophet\lib\site-packages\fbprophet\forecaster.py", line 840, in fit
    **kwargs
  File "C:\Users\ckg\Envs\Prophet\lib\site-packages\pystan\model.py", line 510, in optimizing
    ret, sample = fit._call_sampler(stan_args)
  File "stanfit4anon_model_1988b9d517e3c16daf27a07f09e3de97_2569974802724943130.pyx", line 876, in stanfit4anon_model_1988b9d517e3c16daf27a07f09e3de97_2569974802724943130.StanFit4Model._call_sampler
  File "stanfit4anon_model_1988b9d517e3c16daf27a07f09e3de97_2569974802724943130.pyx", line 401, in stanfit4anon_model_1988b9d517e3c16daf27a07f09e3de97_2569974802724943130._call_sampler
RuntimeError: Initialization failed.
2018-07-22 14:01:25,105 - INFO - __main__ : 250 - ExecuteFunction (functionId: 0)
2018-07-22 14:01:33,385 - ERROR - _server : 411 - Exception iterating responses: Initialization failed.
Traceback (most recent call last):
  File "C:\Users\ckg\Envs\Prophet\lib\site-packages\fbprophet\forecaster.py", line 836, in fit
    dat, init=stan_init, iter=1e4, **kwargs)
  File "C:\Users\ckg\Envs\Prophet\lib\site-packages\pystan\model.py", line 510, in optimizing
    ret, sample = fit._call_sampler(stan_args)
  File "stanfit4anon_model_1988b9d517e3c16daf27a07f09e3de97_2569974802724943130.pyx", line 876, in stanfit4anon_model_1988b9d517e3c16daf27a07f09e3de97_2569974802724943130.StanFit4Model._call_sampler
  File "stanfit4anon_model_1988b9d517e3c16daf27a07f09e3de97_2569974802724943130.pyx", line 401, in stanfit4anon_model_1988b9d517e3c16daf27a07f09e3de97_2569974802724943130._call_sampler
RuntimeError: Initialization failed.

During handling of the above exception, another exception occurred:

Traceback (most recent call last):
  File "C:\Users\ckg\Envs\Prophet\lib\site-packages\grpc\_server.py", line 401, in _take_response_from_response_iterator
    return next(response_iterator), True
  File "__main__.py", line 158, in _prophet
    # fit data to prophet
  File "C:\Users\ckg\Envs\Prophet\lib\site-packages\fbprophet\forecaster.py", line 840, in fit
    **kwargs
  File "C:\Users\ckg\Envs\Prophet\lib\site-packages\pystan\model.py", line 510, in optimizing
    ret, sample = fit._call_sampler(stan_args)
  File "stanfit4anon_model_1988b9d517e3c16daf27a07f09e3de97_2569974802724943130.pyx", line 876, in stanfit4anon_model_1988b9d517e3c16daf27a07f09e3de97_2569974802724943130.StanFit4Model._call_sampler
  File "stanfit4anon_model_1988b9d517e3c16daf27a07f09e3de97_2569974802724943130.pyx", line 401, in stanfit4anon_model_1988b9d517e3c16daf27a07f09e3de97_2569974802724943130._call_sampler
RuntimeError: Initialization failed.
2018-07-22 14:01:34,132 - INFO - __main__ : 250 - ExecuteFunction (functionId: 0)
2018-07-22 14:01:36,183 - ERROR - _server : 411 - Exception iterating responses: Initialization failed.
Traceback (most recent call last):
  File "C:\Users\ckg\Envs\Prophet\lib\site-packages\fbprophet\forecaster.py", line 836, in fit
    dat, init=stan_init, iter=1e4, **kwargs)
  File "C:\Users\ckg\Envs\Prophet\lib\site-packages\pystan\model.py", line 510, in optimizing
    ret, sample = fit._call_sampler(stan_args)
  File "stanfit4anon_model_1988b9d517e3c16daf27a07f09e3de97_2569974802724943130.pyx", line 876, in stanfit4anon_model_1988b9d517e3c16daf27a07f09e3de97_2569974802724943130.StanFit4Model._call_sampler
  File "stanfit4anon_model_1988b9d517e3c16daf27a07f09e3de97_2569974802724943130.pyx", line 401, in stanfit4anon_model_1988b9d517e3c16daf27a07f09e3de97_2569974802724943130._call_sampler
RuntimeError: Initialization failed.

During handling of the above exception, another exception occurred:

Traceback (most recent call last):
  File "C:\Users\ckg\Envs\Prophet\lib\site-packages\grpc\_server.py", line 401, in _take_response_from_response_iterator
    return next(response_iterator), True
  File "__main__.py", line 158, in _prophet
    # fit data to prophet
  File "C:\Users\ckg\Envs\Prophet\lib\site-packages\fbprophet\forecaster.py", line 840, in fit
    **kwargs
  File "C:\Users\ckg\Envs\Prophet\lib\site-packages\pystan\model.py", line 510, in optimizing
    ret, sample = fit._call_sampler(stan_args)
  File "stanfit4anon_model_1988b9d517e3c16daf27a07f09e3de97_2569974802724943130.pyx", line 876, in stanfit4anon_model_1988b9d517e3c16daf27a07f09e3de97_2569974802724943130.StanFit4Model._call_sampler
  File "stanfit4anon_model_1988b9d517e3c16daf27a07f09e3de97_2569974802724943130.pyx", line 401, in stanfit4anon_model_1988b9d517e3c16daf27a07f09e3de97_2569974802724943130._call_sampler
RuntimeError: Initialization failed.
2018-07-22 14:02:28,890 - INFO - __main__ : 250 - ExecuteFunction (functionId: 0)
2018-07-22 14:02:32,928 - ERROR - _server : 411 - Exception iterating responses: Initialization failed.
Traceback (most recent call last):
  File "C:\Users\ckg\Envs\Prophet\lib\site-packages\fbprophet\forecaster.py", line 836, in fit
    dat, init=stan_init, iter=1e4, **kwargs)
  File "C:\Users\ckg\Envs\Prophet\lib\site-packages\pystan\model.py", line 510, in optimizing
    ret, sample = fit._call_sampler(stan_args)
  File "stanfit4anon_model_1988b9d517e3c16daf27a07f09e3de97_2569974802724943130.pyx", line 876, in stanfit4anon_model_1988b9d517e3c16daf27a07f09e3de97_2569974802724943130.StanFit4Model._call_sampler
  File "stanfit4anon_model_1988b9d517e3c16daf27a07f09e3de97_2569974802724943130.pyx", line 401, in stanfit4anon_model_1988b9d517e3c16daf27a07f09e3de97_2569974802724943130._call_sampler
RuntimeError: Initialization failed.

During handling of the above exception, another exception occurred:

Traceback (most recent call last):
  File "C:\Users\ckg\Envs\Prophet\lib\site-packages\grpc\_server.py", line 401, in _take_response_from_response_iterator
    return next(response_iterator), True
  File "__main__.py", line 158, in _prophet
    # fit data to prophet
  File "C:\Users\ckg\Envs\Prophet\lib\site-packages\fbprophet\forecaster.py", line 840, in fit
    **kwargs
  File "C:\Users\ckg\Envs\Prophet\lib\site-packages\pystan\model.py", line 510, in optimizing
    ret, sample = fit._call_sampler(stan_args)
  File "stanfit4anon_model_1988b9d517e3c16daf27a07f09e3de97_2569974802724943130.pyx", line 876, in stanfit4anon_model_1988b9d517e3c16daf27a07f09e3de97_2569974802724943130.StanFit4Model._call_sampler
  File "stanfit4anon_model_1988b9d517e3c16daf27a07f09e3de97_2569974802724943130.pyx", line 401, in stanfit4anon_model_1988b9d517e3c16daf27a07f09e3de97_2569974802724943130._call_sampler
RuntimeError: Initialization failed.
2018-07-22 14:02:32,948 - INFO - __main__ : 250 - ExecuteFunction (functionId: 0)
2018-07-22 14:02:35,178 - ERROR - _server : 411 - Exception iterating responses: Initialization failed.
Traceback (most recent call last):
  File "C:\Users\ckg\Envs\Prophet\lib\site-packages\fbprophet\forecaster.py", line 836, in fit
    dat, init=stan_init, iter=1e4, **kwargs)
  File "C:\Users\ckg\Envs\Prophet\lib\site-packages\pystan\model.py", line 510, in optimizing
    ret, sample = fit._call_sampler(stan_args)
  File "stanfit4anon_model_1988b9d517e3c16daf27a07f09e3de97_2569974802724943130.pyx", line 876, in stanfit4anon_model_1988b9d517e3c16daf27a07f09e3de97_2569974802724943130.StanFit4Model._call_sampler
  File "stanfit4anon_model_1988b9d517e3c16daf27a07f09e3de97_2569974802724943130.pyx", line 401, in stanfit4anon_model_1988b9d517e3c16daf27a07f09e3de97_2569974802724943130._call_sampler
RuntimeError: Initialization failed.

During handling of the above exception, another exception occurred:

Traceback (most recent call last):
  File "C:\Users\ckg\Envs\Prophet\lib\site-packages\grpc\_server.py", line 401, in _take_response_from_response_iterator
    return next(response_iterator), True
  File "__main__.py", line 158, in _prophet
    # fit data to prophet
  File "C:\Users\ckg\Envs\Prophet\lib\site-packages\fbprophet\forecaster.py", line 840, in fit
    **kwargs
  File "C:\Users\ckg\Envs\Prophet\lib\site-packages\pystan\model.py", line 510, in optimizing
    ret, sample = fit._call_sampler(stan_args)
  File "stanfit4anon_model_1988b9d517e3c16daf27a07f09e3de97_2569974802724943130.pyx", line 876, in stanfit4anon_model_1988b9d517e3c16daf27a07f09e3de97_2569974802724943130.StanFit4Model._call_sampler
  File "stanfit4anon_model_1988b9d517e3c16daf27a07f09e3de97_2569974802724943130.pyx", line 401, in stanfit4anon_model_1988b9d517e3c16daf27a07f09e3de97_2569974802724943130._call_sampler
RuntimeError: Initialization failed.
2018-07-22 14:03:31,241 - INFO - __main__ : 44 - Logging enabled
2018-07-22 14:03:31,251 - INFO - __main__ : 314 - *** Running server in insecure mode on port: 50066 ***
2018-07-22 14:03:45,395 - INFO - __main__ : 254 - ExecuteFunction (functionId: 0)
2018-07-22 14:03:57,889 - ERROR - _server : 411 - Exception iterating responses: Initialization failed.
Traceback (most recent call last):
  File "C:\Users\ckg\Envs\Prophet\lib\site-packages\fbprophet\forecaster.py", line 836, in fit
    dat, init=stan_init, iter=1e4, **kwargs)
  File "C:\Users\ckg\Envs\Prophet\lib\site-packages\pystan\model.py", line 510, in optimizing
    ret, sample = fit._call_sampler(stan_args)
  File "stanfit4anon_model_1988b9d517e3c16daf27a07f09e3de97_2569974802724943130.pyx", line 876, in stanfit4anon_model_1988b9d517e3c16daf27a07f09e3de97_2569974802724943130.StanFit4Model._call_sampler
  File "stanfit4anon_model_1988b9d517e3c16daf27a07f09e3de97_2569974802724943130.pyx", line 401, in stanfit4anon_model_1988b9d517e3c16daf27a07f09e3de97_2569974802724943130._call_sampler
RuntimeError: Initialization failed.

During handling of the above exception, another exception occurred:

Traceback (most recent call last):
  File "C:\Users\ckg\Envs\Prophet\lib\site-packages\grpc\_server.py", line 401, in _take_response_from_response_iterator
    return next(response_iterator), True
  File "__main__.py", line 161, in _prophet
    m.fit(dataFrame)
  File "C:\Users\ckg\Envs\Prophet\lib\site-packages\fbprophet\forecaster.py", line 840, in fit
    **kwargs
  File "C:\Users\ckg\Envs\Prophet\lib\site-packages\pystan\model.py", line 510, in optimizing
    ret, sample = fit._call_sampler(stan_args)
  File "stanfit4anon_model_1988b9d517e3c16daf27a07f09e3de97_2569974802724943130.pyx", line 876, in stanfit4anon_model_1988b9d517e3c16daf27a07f09e3de97_2569974802724943130.StanFit4Model._call_sampler
  File "stanfit4anon_model_1988b9d517e3c16daf27a07f09e3de97_2569974802724943130.pyx", line 401, in stanfit4anon_model_1988b9d517e3c16daf27a07f09e3de97_2569974802724943130._call_sampler
RuntimeError: Initialization failed.
2018-07-22 14:03:57,914 - INFO - __main__ : 254 - ExecuteFunction (functionId: 0)
2018-07-22 14:04:01,126 - ERROR - _server : 411 - Exception iterating responses: Initialization failed.
Traceback (most recent call last):
  File "C:\Users\ckg\Envs\Prophet\lib\site-packages\fbprophet\forecaster.py", line 836, in fit
    dat, init=stan_init, iter=1e4, **kwargs)
  File "C:\Users\ckg\Envs\Prophet\lib\site-packages\pystan\model.py", line 510, in optimizing
    ret, sample = fit._call_sampler(stan_args)
  File "stanfit4anon_model_1988b9d517e3c16daf27a07f09e3de97_2569974802724943130.pyx", line 876, in stanfit4anon_model_1988b9d517e3c16daf27a07f09e3de97_2569974802724943130.StanFit4Model._call_sampler
  File "stanfit4anon_model_1988b9d517e3c16daf27a07f09e3de97_2569974802724943130.pyx", line 401, in stanfit4anon_model_1988b9d517e3c16daf27a07f09e3de97_2569974802724943130._call_sampler
RuntimeError: Initialization failed.

During handling of the above exception, another exception occurred:

Traceback (most recent call last):
  File "C:\Users\ckg\Envs\Prophet\lib\site-packages\grpc\_server.py", line 401, in _take_response_from_response_iterator
    return next(response_iterator), True
  File "__main__.py", line 161, in _prophet
    m.fit(dataFrame)
  File "C:\Users\ckg\Envs\Prophet\lib\site-packages\fbprophet\forecaster.py", line 840, in fit
    **kwargs
  File "C:\Users\ckg\Envs\Prophet\lib\site-packages\pystan\model.py", line 510, in optimizing
    ret, sample = fit._call_sampler(stan_args)
  File "stanfit4anon_model_1988b9d517e3c16daf27a07f09e3de97_2569974802724943130.pyx", line 876, in stanfit4anon_model_1988b9d517e3c16daf27a07f09e3de97_2569974802724943130.StanFit4Model._call_sampler
  File "stanfit4anon_model_1988b9d517e3c16daf27a07f09e3de97_2569974802724943130.pyx", line 401, in stanfit4anon_model_1988b9d517e3c16daf27a07f09e3de97_2569974802724943130._call_sampler
RuntimeError: Initialization failed.
2018-07-22 14:05:39,301 - INFO - __main__ : 44 - Logging enabled
2018-07-22 14:05:39,312 - INFO - __main__ : 314 - *** Running server in insecure mode on port: 50066 ***
2018-07-22 14:05:48,347 - INFO - __main__ : 254 - ExecuteFunction (functionId: 0)
2018-07-22 14:05:57,112 - ERROR - _server : 411 - Exception iterating responses: Initialization failed.
Traceback (most recent call last):
  File "C:\Users\ckg\Envs\Prophet\lib\site-packages\fbprophet\forecaster.py", line 836, in fit
    dat, init=stan_init, iter=1e4, **kwargs)
  File "C:\Users\ckg\Envs\Prophet\lib\site-packages\pystan\model.py", line 510, in optimizing
    ret, sample = fit._call_sampler(stan_args)
  File "stanfit4anon_model_1988b9d517e3c16daf27a07f09e3de97_2569974802724943130.pyx", line 876, in stanfit4anon_model_1988b9d517e3c16daf27a07f09e3de97_2569974802724943130.StanFit4Model._call_sampler
  File "stanfit4anon_model_1988b9d517e3c16daf27a07f09e3de97_2569974802724943130.pyx", line 401, in stanfit4anon_model_1988b9d517e3c16daf27a07f09e3de97_2569974802724943130._call_sampler
RuntimeError: Initialization failed.

During handling of the above exception, another exception occurred:

Traceback (most recent call last):
  File "C:\Users\ckg\Envs\Prophet\lib\site-packages\grpc\_server.py", line 401, in _take_response_from_response_iterator
    return next(response_iterator), True
  File "__main__.py", line 161, in _prophet
    m.fit(dataFrame)
  File "C:\Users\ckg\Envs\Prophet\lib\site-packages\fbprophet\forecaster.py", line 840, in fit
    **kwargs
  File "C:\Users\ckg\Envs\Prophet\lib\site-packages\pystan\model.py", line 510, in optimizing
    ret, sample = fit._call_sampler(stan_args)
  File "stanfit4anon_model_1988b9d517e3c16daf27a07f09e3de97_2569974802724943130.pyx", line 876, in stanfit4anon_model_1988b9d517e3c16daf27a07f09e3de97_2569974802724943130.StanFit4Model._call_sampler
  File "stanfit4anon_model_1988b9d517e3c16daf27a07f09e3de97_2569974802724943130.pyx", line 401, in stanfit4anon_model_1988b9d517e3c16daf27a07f09e3de97_2569974802724943130._call_sampler
RuntimeError: Initialization failed.
2018-07-22 14:05:57,889 - INFO - __main__ : 254 - ExecuteFunction (functionId: 0)
2018-07-22 14:06:00,162 - ERROR - _server : 411 - Exception iterating responses: Initialization failed.
Traceback (most recent call last):
  File "C:\Users\ckg\Envs\Prophet\lib\site-packages\fbprophet\forecaster.py", line 836, in fit
    dat, init=stan_init, iter=1e4, **kwargs)
  File "C:\Users\ckg\Envs\Prophet\lib\site-packages\pystan\model.py", line 510, in optimizing
    ret, sample = fit._call_sampler(stan_args)
  File "stanfit4anon_model_1988b9d517e3c16daf27a07f09e3de97_2569974802724943130.pyx", line 876, in stanfit4anon_model_1988b9d517e3c16daf27a07f09e3de97_2569974802724943130.StanFit4Model._call_sampler
  File "stanfit4anon_model_1988b9d517e3c16daf27a07f09e3de97_2569974802724943130.pyx", line 401, in stanfit4anon_model_1988b9d517e3c16daf27a07f09e3de97_2569974802724943130._call_sampler
RuntimeError: Initialization failed.

During handling of the above exception, another exception occurred:

Traceback (most recent call last):
  File "C:\Users\ckg\Envs\Prophet\lib\site-packages\grpc\_server.py", line 401, in _take_response_from_response_iterator
    return next(response_iterator), True
  File "__main__.py", line 161, in _prophet
    m.fit(dataFrame)
  File "C:\Users\ckg\Envs\Prophet\lib\site-packages\fbprophet\forecaster.py", line 840, in fit
    **kwargs
  File "C:\Users\ckg\Envs\Prophet\lib\site-packages\pystan\model.py", line 510, in optimizing
    ret, sample = fit._call_sampler(stan_args)
  File "stanfit4anon_model_1988b9d517e3c16daf27a07f09e3de97_2569974802724943130.pyx", line 876, in stanfit4anon_model_1988b9d517e3c16daf27a07f09e3de97_2569974802724943130.StanFit4Model._call_sampler
  File "stanfit4anon_model_1988b9d517e3c16daf27a07f09e3de97_2569974802724943130.pyx", line 401, in stanfit4anon_model_1988b9d517e3c16daf27a07f09e3de97_2569974802724943130._call_sampler
RuntimeError: Initialization failed.
2018-07-22 14:08:10,211 - INFO - __main__ : 44 - Logging enabled
2018-07-22 14:08:10,221 - INFO - __main__ : 314 - *** Running server in insecure mode on port: 50066 ***
2018-07-22 14:08:19,680 - INFO - __main__ : 254 - ExecuteFunction (functionId: 0)
2018-07-22 14:08:28,386 - ERROR - _server : 411 - Exception iterating responses: Initialization failed.
Traceback (most recent call last):
  File "C:\Users\ckg\Envs\Prophet\lib\site-packages\fbprophet\forecaster.py", line 836, in fit
    dat, init=stan_init, iter=1e4, **kwargs)
  File "C:\Users\ckg\Envs\Prophet\lib\site-packages\pystan\model.py", line 510, in optimizing
    ret, sample = fit._call_sampler(stan_args)
  File "stanfit4anon_model_1988b9d517e3c16daf27a07f09e3de97_2569974802724943130.pyx", line 876, in stanfit4anon_model_1988b9d517e3c16daf27a07f09e3de97_2569974802724943130.StanFit4Model._call_sampler
  File "stanfit4anon_model_1988b9d517e3c16daf27a07f09e3de97_2569974802724943130.pyx", line 401, in stanfit4anon_model_1988b9d517e3c16daf27a07f09e3de97_2569974802724943130._call_sampler
RuntimeError: Initialization failed.

During handling of the above exception, another exception occurred:

Traceback (most recent call last):
  File "C:\Users\ckg\Envs\Prophet\lib\site-packages\grpc\_server.py", line 401, in _take_response_from_response_iterator
    return next(response_iterator), True
  File "__main__.py", line 161, in _prophet
    m.fit(dataFrame)
  File "C:\Users\ckg\Envs\Prophet\lib\site-packages\fbprophet\forecaster.py", line 840, in fit
    **kwargs
  File "C:\Users\ckg\Envs\Prophet\lib\site-packages\pystan\model.py", line 510, in optimizing
    ret, sample = fit._call_sampler(stan_args)
  File "stanfit4anon_model_1988b9d517e3c16daf27a07f09e3de97_2569974802724943130.pyx", line 876, in stanfit4anon_model_1988b9d517e3c16daf27a07f09e3de97_2569974802724943130.StanFit4Model._call_sampler
  File "stanfit4anon_model_1988b9d517e3c16daf27a07f09e3de97_2569974802724943130.pyx", line 401, in stanfit4anon_model_1988b9d517e3c16daf27a07f09e3de97_2569974802724943130._call_sampler
RuntimeError: Initialization failed.
2018-07-22 14:08:28,410 - INFO - __main__ : 254 - ExecuteFunction (functionId: 0)
2018-07-22 14:08:31,039 - ERROR - _server : 411 - Exception iterating responses: Initialization failed.
Traceback (most recent call last):
  File "C:\Users\ckg\Envs\Prophet\lib\site-packages\fbprophet\forecaster.py", line 836, in fit
    dat, init=stan_init, iter=1e4, **kwargs)
  File "C:\Users\ckg\Envs\Prophet\lib\site-packages\pystan\model.py", line 510, in optimizing
    ret, sample = fit._call_sampler(stan_args)
  File "stanfit4anon_model_1988b9d517e3c16daf27a07f09e3de97_2569974802724943130.pyx", line 876, in stanfit4anon_model_1988b9d517e3c16daf27a07f09e3de97_2569974802724943130.StanFit4Model._call_sampler
  File "stanfit4anon_model_1988b9d517e3c16daf27a07f09e3de97_2569974802724943130.pyx", line 401, in stanfit4anon_model_1988b9d517e3c16daf27a07f09e3de97_2569974802724943130._call_sampler
RuntimeError: Initialization failed.

During handling of the above exception, another exception occurred:

Traceback (most recent call last):
  File "C:\Users\ckg\Envs\Prophet\lib\site-packages\grpc\_server.py", line 401, in _take_response_from_response_iterator
    return next(response_iterator), True
  File "__main__.py", line 161, in _prophet
    m.fit(dataFrame)
  File "C:\Users\ckg\Envs\Prophet\lib\site-packages\fbprophet\forecaster.py", line 840, in fit
    **kwargs
  File "C:\Users\ckg\Envs\Prophet\lib\site-packages\pystan\model.py", line 510, in optimizing
    ret, sample = fit._call_sampler(stan_args)
  File "stanfit4anon_model_1988b9d517e3c16daf27a07f09e3de97_2569974802724943130.pyx", line 876, in stanfit4anon_model_1988b9d517e3c16daf27a07f09e3de97_2569974802724943130.StanFit4Model._call_sampler
  File "stanfit4anon_model_1988b9d517e3c16daf27a07f09e3de97_2569974802724943130.pyx", line 401, in stanfit4anon_model_1988b9d517e3c16daf27a07f09e3de97_2569974802724943130._call_sampler
RuntimeError: Initialization failed.
2018-07-22 14:10:01,889 - INFO - __main__ : 44 - Logging enabled
2018-07-22 14:10:01,900 - INFO - __main__ : 314 - *** Running server in insecure mode on port: 50066 ***
2018-07-22 14:11:14,236 - INFO - __main__ : 254 - ExecuteFunction (functionId: 0)
2018-07-22 14:11:23,190 - ERROR - _server : 411 - Exception iterating responses: Initialization failed.
Traceback (most recent call last):
  File "C:\Users\ckg\Envs\Prophet\lib\site-packages\fbprophet\forecaster.py", line 836, in fit
    dat, init=stan_init, iter=1e4, **kwargs)
  File "C:\Users\ckg\Envs\Prophet\lib\site-packages\pystan\model.py", line 510, in optimizing
    ret, sample = fit._call_sampler(stan_args)
  File "stanfit4anon_model_1988b9d517e3c16daf27a07f09e3de97_2569974802724943130.pyx", line 876, in stanfit4anon_model_1988b9d517e3c16daf27a07f09e3de97_2569974802724943130.StanFit4Model._call_sampler
  File "stanfit4anon_model_1988b9d517e3c16daf27a07f09e3de97_2569974802724943130.pyx", line 401, in stanfit4anon_model_1988b9d517e3c16daf27a07f09e3de97_2569974802724943130._call_sampler
RuntimeError: Initialization failed.

During handling of the above exception, another exception occurred:

Traceback (most recent call last):
  File "C:\Users\ckg\Envs\Prophet\lib\site-packages\grpc\_server.py", line 401, in _take_response_from_response_iterator
    return next(response_iterator), True
  File "__main__.py", line 161, in _prophet
    m.fit(dataFrame)
  File "C:\Users\ckg\Envs\Prophet\lib\site-packages\fbprophet\forecaster.py", line 840, in fit
    **kwargs
  File "C:\Users\ckg\Envs\Prophet\lib\site-packages\pystan\model.py", line 510, in optimizing
    ret, sample = fit._call_sampler(stan_args)
  File "stanfit4anon_model_1988b9d517e3c16daf27a07f09e3de97_2569974802724943130.pyx", line 876, in stanfit4anon_model_1988b9d517e3c16daf27a07f09e3de97_2569974802724943130.StanFit4Model._call_sampler
  File "stanfit4anon_model_1988b9d517e3c16daf27a07f09e3de97_2569974802724943130.pyx", line 401, in stanfit4anon_model_1988b9d517e3c16daf27a07f09e3de97_2569974802724943130._call_sampler
RuntimeError: Initialization failed.
2018-07-22 14:11:23,200 - INFO - __main__ : 254 - ExecuteFunction (functionId: 0)
2018-07-22 14:11:25,285 - ERROR - _server : 411 - Exception iterating responses: Initialization failed.
Traceback (most recent call last):
  File "C:\Users\ckg\Envs\Prophet\lib\site-packages\fbprophet\forecaster.py", line 836, in fit
    dat, init=stan_init, iter=1e4, **kwargs)
  File "C:\Users\ckg\Envs\Prophet\lib\site-packages\pystan\model.py", line 510, in optimizing
    ret, sample = fit._call_sampler(stan_args)
  File "stanfit4anon_model_1988b9d517e3c16daf27a07f09e3de97_2569974802724943130.pyx", line 876, in stanfit4anon_model_1988b9d517e3c16daf27a07f09e3de97_2569974802724943130.StanFit4Model._call_sampler
  File "stanfit4anon_model_1988b9d517e3c16daf27a07f09e3de97_2569974802724943130.pyx", line 401, in stanfit4anon_model_1988b9d517e3c16daf27a07f09e3de97_2569974802724943130._call_sampler
RuntimeError: Initialization failed.

During handling of the above exception, another exception occurred:

Traceback (most recent call last):
  File "C:\Users\ckg\Envs\Prophet\lib\site-packages\grpc\_server.py", line 401, in _take_response_from_response_iterator
    return next(response_iterator), True
  File "__main__.py", line 161, in _prophet
    m.fit(dataFrame)
  File "C:\Users\ckg\Envs\Prophet\lib\site-packages\fbprophet\forecaster.py", line 840, in fit
    **kwargs
  File "C:\Users\ckg\Envs\Prophet\lib\site-packages\pystan\model.py", line 510, in optimizing
    ret, sample = fit._call_sampler(stan_args)
  File "stanfit4anon_model_1988b9d517e3c16daf27a07f09e3de97_2569974802724943130.pyx", line 876, in stanfit4anon_model_1988b9d517e3c16daf27a07f09e3de97_2569974802724943130.StanFit4Model._call_sampler
  File "stanfit4anon_model_1988b9d517e3c16daf27a07f09e3de97_2569974802724943130.pyx", line 401, in stanfit4anon_model_1988b9d517e3c16daf27a07f09e3de97_2569974802724943130._call_sampler
RuntimeError: Initialization failed.
2018-07-22 14:12:29,134 - INFO - __main__ : 44 - Logging enabled
2018-07-22 14:12:29,146 - INFO - __main__ : 313 - *** Running server in insecure mode on port: 50066 ***
2018-07-22 14:13:01,823 - INFO - __main__ : 253 - ExecuteFunction (functionId: 0)
2018-07-22 14:13:10,367 - ERROR - _server : 411 - Exception iterating responses: Initialization failed.
Traceback (most recent call last):
  File "C:\Users\ckg\Envs\Prophet\lib\site-packages\fbprophet\forecaster.py", line 836, in fit
    dat, init=stan_init, iter=1e4, **kwargs)
  File "C:\Users\ckg\Envs\Prophet\lib\site-packages\pystan\model.py", line 510, in optimizing
    ret, sample = fit._call_sampler(stan_args)
  File "stanfit4anon_model_1988b9d517e3c16daf27a07f09e3de97_2569974802724943130.pyx", line 876, in stanfit4anon_model_1988b9d517e3c16daf27a07f09e3de97_2569974802724943130.StanFit4Model._call_sampler
  File "stanfit4anon_model_1988b9d517e3c16daf27a07f09e3de97_2569974802724943130.pyx", line 401, in stanfit4anon_model_1988b9d517e3c16daf27a07f09e3de97_2569974802724943130._call_sampler
RuntimeError: Initialization failed.

During handling of the above exception, another exception occurred:

Traceback (most recent call last):
  File "C:\Users\ckg\Envs\Prophet\lib\site-packages\grpc\_server.py", line 401, in _take_response_from_response_iterator
    return next(response_iterator), True
  File "__main__.py", line 160, in _prophet
    m.fit(dataFrame)
  File "C:\Users\ckg\Envs\Prophet\lib\site-packages\fbprophet\forecaster.py", line 840, in fit
    **kwargs
  File "C:\Users\ckg\Envs\Prophet\lib\site-packages\pystan\model.py", line 510, in optimizing
    ret, sample = fit._call_sampler(stan_args)
  File "stanfit4anon_model_1988b9d517e3c16daf27a07f09e3de97_2569974802724943130.pyx", line 876, in stanfit4anon_model_1988b9d517e3c16daf27a07f09e3de97_2569974802724943130.StanFit4Model._call_sampler
  File "stanfit4anon_model_1988b9d517e3c16daf27a07f09e3de97_2569974802724943130.pyx", line 401, in stanfit4anon_model_1988b9d517e3c16daf27a07f09e3de97_2569974802724943130._call_sampler
RuntimeError: Initialization failed.
2018-07-22 14:13:12,606 - INFO - __main__ : 253 - ExecuteFunction (functionId: 0)
2018-07-22 14:13:15,166 - ERROR - _server : 411 - Exception iterating responses: Initialization failed.
Traceback (most recent call last):
  File "C:\Users\ckg\Envs\Prophet\lib\site-packages\fbprophet\forecaster.py", line 836, in fit
    dat, init=stan_init, iter=1e4, **kwargs)
  File "C:\Users\ckg\Envs\Prophet\lib\site-packages\pystan\model.py", line 510, in optimizing
    ret, sample = fit._call_sampler(stan_args)
  File "stanfit4anon_model_1988b9d517e3c16daf27a07f09e3de97_2569974802724943130.pyx", line 876, in stanfit4anon_model_1988b9d517e3c16daf27a07f09e3de97_2569974802724943130.StanFit4Model._call_sampler
  File "stanfit4anon_model_1988b9d517e3c16daf27a07f09e3de97_2569974802724943130.pyx", line 401, in stanfit4anon_model_1988b9d517e3c16daf27a07f09e3de97_2569974802724943130._call_sampler
RuntimeError: Initialization failed.

During handling of the above exception, another exception occurred:

Traceback (most recent call last):
  File "C:\Users\ckg\Envs\Prophet\lib\site-packages\grpc\_server.py", line 401, in _take_response_from_response_iterator
    return next(response_iterator), True
  File "__main__.py", line 160, in _prophet
    m.fit(dataFrame)
  File "C:\Users\ckg\Envs\Prophet\lib\site-packages\fbprophet\forecaster.py", line 840, in fit
    **kwargs
  File "C:\Users\ckg\Envs\Prophet\lib\site-packages\pystan\model.py", line 510, in optimizing
    ret, sample = fit._call_sampler(stan_args)
  File "stanfit4anon_model_1988b9d517e3c16daf27a07f09e3de97_2569974802724943130.pyx", line 876, in stanfit4anon_model_1988b9d517e3c16daf27a07f09e3de97_2569974802724943130.StanFit4Model._call_sampler
  File "stanfit4anon_model_1988b9d517e3c16daf27a07f09e3de97_2569974802724943130.pyx", line 401, in stanfit4anon_model_1988b9d517e3c16daf27a07f09e3de97_2569974802724943130._call_sampler
RuntimeError: Initialization failed.
2018-07-22 14:15:55,912 - INFO - __main__ : 44 - Logging enabled
2018-07-22 14:15:55,922 - INFO - __main__ : 312 - *** Running server in insecure mode on port: 50066 ***
2018-07-22 14:16:28,463 - INFO - __main__ : 252 - ExecuteFunction (functionId: 0)
2018-07-22 14:16:37,348 - ERROR - _server : 411 - Exception iterating responses: Initialization failed.
Traceback (most recent call last):
  File "C:\Users\ckg\Envs\Prophet\lib\site-packages\fbprophet\forecaster.py", line 836, in fit
    dat, init=stan_init, iter=1e4, **kwargs)
  File "C:\Users\ckg\Envs\Prophet\lib\site-packages\pystan\model.py", line 510, in optimizing
    ret, sample = fit._call_sampler(stan_args)
  File "stanfit4anon_model_1988b9d517e3c16daf27a07f09e3de97_2569974802724943130.pyx", line 876, in stanfit4anon_model_1988b9d517e3c16daf27a07f09e3de97_2569974802724943130.StanFit4Model._call_sampler
  File "stanfit4anon_model_1988b9d517e3c16daf27a07f09e3de97_2569974802724943130.pyx", line 401, in stanfit4anon_model_1988b9d517e3c16daf27a07f09e3de97_2569974802724943130._call_sampler
RuntimeError: Initialization failed.

During handling of the above exception, another exception occurred:

Traceback (most recent call last):
  File "C:\Users\ckg\Envs\Prophet\lib\site-packages\grpc\_server.py", line 401, in _take_response_from_response_iterator
    return next(response_iterator), True
  File "__main__.py", line 159, in _prophet
    m.fit(dataFrame)
  File "C:\Users\ckg\Envs\Prophet\lib\site-packages\fbprophet\forecaster.py", line 840, in fit
    **kwargs
  File "C:\Users\ckg\Envs\Prophet\lib\site-packages\pystan\model.py", line 510, in optimizing
    ret, sample = fit._call_sampler(stan_args)
  File "stanfit4anon_model_1988b9d517e3c16daf27a07f09e3de97_2569974802724943130.pyx", line 876, in stanfit4anon_model_1988b9d517e3c16daf27a07f09e3de97_2569974802724943130.StanFit4Model._call_sampler
  File "stanfit4anon_model_1988b9d517e3c16daf27a07f09e3de97_2569974802724943130.pyx", line 401, in stanfit4anon_model_1988b9d517e3c16daf27a07f09e3de97_2569974802724943130._call_sampler
RuntimeError: Initialization failed.
2018-07-22 14:16:37,379 - INFO - __main__ : 252 - ExecuteFunction (functionId: 0)
2018-07-22 14:16:39,692 - ERROR - _server : 411 - Exception iterating responses: Initialization failed.
Traceback (most recent call last):
  File "C:\Users\ckg\Envs\Prophet\lib\site-packages\fbprophet\forecaster.py", line 836, in fit
    dat, init=stan_init, iter=1e4, **kwargs)
  File "C:\Users\ckg\Envs\Prophet\lib\site-packages\pystan\model.py", line 510, in optimizing
    ret, sample = fit._call_sampler(stan_args)
  File "stanfit4anon_model_1988b9d517e3c16daf27a07f09e3de97_2569974802724943130.pyx", line 876, in stanfit4anon_model_1988b9d517e3c16daf27a07f09e3de97_2569974802724943130.StanFit4Model._call_sampler
  File "stanfit4anon_model_1988b9d517e3c16daf27a07f09e3de97_2569974802724943130.pyx", line 401, in stanfit4anon_model_1988b9d517e3c16daf27a07f09e3de97_2569974802724943130._call_sampler
RuntimeError: Initialization failed.

During handling of the above exception, another exception occurred:

Traceback (most recent call last):
  File "C:\Users\ckg\Envs\Prophet\lib\site-packages\grpc\_server.py", line 401, in _take_response_from_response_iterator
    return next(response_iterator), True
  File "__main__.py", line 159, in _prophet
    m.fit(dataFrame)
  File "C:\Users\ckg\Envs\Prophet\lib\site-packages\fbprophet\forecaster.py", line 840, in fit
    **kwargs
  File "C:\Users\ckg\Envs\Prophet\lib\site-packages\pystan\model.py", line 510, in optimizing
    ret, sample = fit._call_sampler(stan_args)
  File "stanfit4anon_model_1988b9d517e3c16daf27a07f09e3de97_2569974802724943130.pyx", line 876, in stanfit4anon_model_1988b9d517e3c16daf27a07f09e3de97_2569974802724943130.StanFit4Model._call_sampler
  File "stanfit4anon_model_1988b9d517e3c16daf27a07f09e3de97_2569974802724943130.pyx", line 401, in stanfit4anon_model_1988b9d517e3c16daf27a07f09e3de97_2569974802724943130._call_sampler
RuntimeError: Initialization failed.
2018-07-22 14:48:16,084 - INFO - __main__ : 44 - Logging enabled
2018-07-22 14:48:16,096 - INFO - __main__ : 314 - *** Running server in insecure mode on port: 50066 ***
2018-07-22 14:48:34,683 - INFO - __main__ : 254 - ExecuteFunction (functionId: 0)
2018-07-22 14:48:34,701 - ERROR - _server : 411 - Exception iterating responses: 'Dual' object is not subscriptable
Traceback (most recent call last):
  File "C:\Users\ckg\Envs\Prophet\lib\site-packages\grpc\_server.py", line 401, in _take_response_from_response_iterator
    return next(response_iterator), True
  File "__main__.py", line 104, in _prophet
    print(row.duals[0]["numData"])
TypeError: 'Dual' object is not subscriptable
2018-07-22 14:48:34,746 - INFO - __main__ : 254 - ExecuteFunction (functionId: 0)
2018-07-22 14:48:34,783 - ERROR - _server : 411 - Exception iterating responses: 'Dual' object is not subscriptable
Traceback (most recent call last):
  File "C:\Users\ckg\Envs\Prophet\lib\site-packages\grpc\_server.py", line 401, in _take_response_from_response_iterator
    return next(response_iterator), True
  File "__main__.py", line 104, in _prophet
    print(row.duals[0]["numData"])
TypeError: 'Dual' object is not subscriptable
2018-07-22 14:50:02,786 - INFO - __main__ : 44 - Logging enabled
2018-07-22 14:50:02,796 - INFO - __main__ : 312 - *** Running server in insecure mode on port: 50066 ***
2018-07-22 14:50:31,599 - INFO - __main__ : 252 - ExecuteFunction (functionId: 0)
2018-07-22 14:50:40,237 - ERROR - _server : 411 - Exception iterating responses: Initialization failed.
Traceback (most recent call last):
  File "C:\Users\ckg\Envs\Prophet\lib\site-packages\fbprophet\forecaster.py", line 836, in fit
    dat, init=stan_init, iter=1e4, **kwargs)
  File "C:\Users\ckg\Envs\Prophet\lib\site-packages\pystan\model.py", line 510, in optimizing
    ret, sample = fit._call_sampler(stan_args)
  File "stanfit4anon_model_1988b9d517e3c16daf27a07f09e3de97_2569974802724943130.pyx", line 876, in stanfit4anon_model_1988b9d517e3c16daf27a07f09e3de97_2569974802724943130.StanFit4Model._call_sampler
  File "stanfit4anon_model_1988b9d517e3c16daf27a07f09e3de97_2569974802724943130.pyx", line 401, in stanfit4anon_model_1988b9d517e3c16daf27a07f09e3de97_2569974802724943130._call_sampler
RuntimeError: Initialization failed.

During handling of the above exception, another exception occurred:

Traceback (most recent call last):
  File "C:\Users\ckg\Envs\Prophet\lib\site-packages\grpc\_server.py", line 401, in _take_response_from_response_iterator
    return next(response_iterator), True
  File "__main__.py", line 159, in _prophet
    m.fit(dataFrame)
  File "C:\Users\ckg\Envs\Prophet\lib\site-packages\fbprophet\forecaster.py", line 840, in fit
    **kwargs
  File "C:\Users\ckg\Envs\Prophet\lib\site-packages\pystan\model.py", line 510, in optimizing
    ret, sample = fit._call_sampler(stan_args)
  File "stanfit4anon_model_1988b9d517e3c16daf27a07f09e3de97_2569974802724943130.pyx", line 876, in stanfit4anon_model_1988b9d517e3c16daf27a07f09e3de97_2569974802724943130.StanFit4Model._call_sampler
  File "stanfit4anon_model_1988b9d517e3c16daf27a07f09e3de97_2569974802724943130.pyx", line 401, in stanfit4anon_model_1988b9d517e3c16daf27a07f09e3de97_2569974802724943130._call_sampler
RuntimeError: Initialization failed.
2018-07-22 14:50:40,262 - INFO - __main__ : 252 - ExecuteFunction (functionId: 0)
2018-07-22 14:50:42,730 - ERROR - _server : 411 - Exception iterating responses: Initialization failed.
Traceback (most recent call last):
  File "C:\Users\ckg\Envs\Prophet\lib\site-packages\fbprophet\forecaster.py", line 836, in fit
    dat, init=stan_init, iter=1e4, **kwargs)
  File "C:\Users\ckg\Envs\Prophet\lib\site-packages\pystan\model.py", line 510, in optimizing
    ret, sample = fit._call_sampler(stan_args)
  File "stanfit4anon_model_1988b9d517e3c16daf27a07f09e3de97_2569974802724943130.pyx", line 876, in stanfit4anon_model_1988b9d517e3c16daf27a07f09e3de97_2569974802724943130.StanFit4Model._call_sampler
  File "stanfit4anon_model_1988b9d517e3c16daf27a07f09e3de97_2569974802724943130.pyx", line 401, in stanfit4anon_model_1988b9d517e3c16daf27a07f09e3de97_2569974802724943130._call_sampler
RuntimeError: Initialization failed.

During handling of the above exception, another exception occurred:

Traceback (most recent call last):
  File "C:\Users\ckg\Envs\Prophet\lib\site-packages\grpc\_server.py", line 401, in _take_response_from_response_iterator
    return next(response_iterator), True
  File "__main__.py", line 159, in _prophet
    m.fit(dataFrame)
  File "C:\Users\ckg\Envs\Prophet\lib\site-packages\fbprophet\forecaster.py", line 840, in fit
    **kwargs
  File "C:\Users\ckg\Envs\Prophet\lib\site-packages\pystan\model.py", line 510, in optimizing
    ret, sample = fit._call_sampler(stan_args)
  File "stanfit4anon_model_1988b9d517e3c16daf27a07f09e3de97_2569974802724943130.pyx", line 876, in stanfit4anon_model_1988b9d517e3c16daf27a07f09e3de97_2569974802724943130.StanFit4Model._call_sampler
  File "stanfit4anon_model_1988b9d517e3c16daf27a07f09e3de97_2569974802724943130.pyx", line 401, in stanfit4anon_model_1988b9d517e3c16daf27a07f09e3de97_2569974802724943130._call_sampler
RuntimeError: Initialization failed.
2018-07-22 14:52:03,932 - INFO - __main__ : 252 - ExecuteFunction (functionId: 0)
2018-07-22 14:52:03,933 - INFO - __main__ : 252 - ExecuteFunction (functionId: 0)
2018-07-22 14:52:05,277 - ERROR - _server : 411 - Exception iterating responses: Initialization failed.
Traceback (most recent call last):
  File "C:\Users\ckg\Envs\Prophet\lib\site-packages\fbprophet\forecaster.py", line 836, in fit
    dat, init=stan_init, iter=1e4, **kwargs)
  File "C:\Users\ckg\Envs\Prophet\lib\site-packages\pystan\model.py", line 510, in optimizing
    ret, sample = fit._call_sampler(stan_args)
  File "stanfit4anon_model_1988b9d517e3c16daf27a07f09e3de97_2569974802724943130.pyx", line 876, in stanfit4anon_model_1988b9d517e3c16daf27a07f09e3de97_2569974802724943130.StanFit4Model._call_sampler
  File "stanfit4anon_model_1988b9d517e3c16daf27a07f09e3de97_2569974802724943130.pyx", line 401, in stanfit4anon_model_1988b9d517e3c16daf27a07f09e3de97_2569974802724943130._call_sampler
RuntimeError: Initialization failed.

During handling of the above exception, another exception occurred:

Traceback (most recent call last):
  File "C:\Users\ckg\Envs\Prophet\lib\site-packages\grpc\_server.py", line 401, in _take_response_from_response_iterator
    return next(response_iterator), True
  File "__main__.py", line 159, in _prophet
    m.fit(dataFrame)
  File "C:\Users\ckg\Envs\Prophet\lib\site-packages\fbprophet\forecaster.py", line 840, in fit
    **kwargs
  File "C:\Users\ckg\Envs\Prophet\lib\site-packages\pystan\model.py", line 510, in optimizing
    ret, sample = fit._call_sampler(stan_args)
  File "stanfit4anon_model_1988b9d517e3c16daf27a07f09e3de97_2569974802724943130.pyx", line 876, in stanfit4anon_model_1988b9d517e3c16daf27a07f09e3de97_2569974802724943130.StanFit4Model._call_sampler
  File "stanfit4anon_model_1988b9d517e3c16daf27a07f09e3de97_2569974802724943130.pyx", line 401, in stanfit4anon_model_1988b9d517e3c16daf27a07f09e3de97_2569974802724943130._call_sampler
RuntimeError: Initialization failed.
2018-07-22 14:52:06,546 - ERROR - _server : 411 - Exception iterating responses: Initialization failed.
Traceback (most recent call last):
  File "C:\Users\ckg\Envs\Prophet\lib\site-packages\fbprophet\forecaster.py", line 836, in fit
    dat, init=stan_init, iter=1e4, **kwargs)
  File "C:\Users\ckg\Envs\Prophet\lib\site-packages\pystan\model.py", line 510, in optimizing
    ret, sample = fit._call_sampler(stan_args)
  File "stanfit4anon_model_1988b9d517e3c16daf27a07f09e3de97_2569974802724943130.pyx", line 876, in stanfit4anon_model_1988b9d517e3c16daf27a07f09e3de97_2569974802724943130.StanFit4Model._call_sampler
  File "stanfit4anon_model_1988b9d517e3c16daf27a07f09e3de97_2569974802724943130.pyx", line 401, in stanfit4anon_model_1988b9d517e3c16daf27a07f09e3de97_2569974802724943130._call_sampler
RuntimeError: Initialization failed.

During handling of the above exception, another exception occurred:

Traceback (most recent call last):
  File "C:\Users\ckg\Envs\Prophet\lib\site-packages\grpc\_server.py", line 401, in _take_response_from_response_iterator
    return next(response_iterator), True
  File "__main__.py", line 159, in _prophet
    m.fit(dataFrame)
  File "C:\Users\ckg\Envs\Prophet\lib\site-packages\fbprophet\forecaster.py", line 840, in fit
    **kwargs
  File "C:\Users\ckg\Envs\Prophet\lib\site-packages\pystan\model.py", line 510, in optimizing
    ret, sample = fit._call_sampler(stan_args)
  File "stanfit4anon_model_1988b9d517e3c16daf27a07f09e3de97_2569974802724943130.pyx", line 876, in stanfit4anon_model_1988b9d517e3c16daf27a07f09e3de97_2569974802724943130.StanFit4Model._call_sampler
  File "stanfit4anon_model_1988b9d517e3c16daf27a07f09e3de97_2569974802724943130.pyx", line 401, in stanfit4anon_model_1988b9d517e3c16daf27a07f09e3de97_2569974802724943130._call_sampler
RuntimeError: Initialization failed.
2018-07-22 14:52:14,318 - INFO - __main__ : 252 - ExecuteFunction (functionId: 0)
2018-07-22 14:52:15,475 - ERROR - _server : 411 - Exception iterating responses: Initialization failed.
Traceback (most recent call last):
  File "C:\Users\ckg\Envs\Prophet\lib\site-packages\fbprophet\forecaster.py", line 836, in fit
    dat, init=stan_init, iter=1e4, **kwargs)
  File "C:\Users\ckg\Envs\Prophet\lib\site-packages\pystan\model.py", line 510, in optimizing
    ret, sample = fit._call_sampler(stan_args)
  File "stanfit4anon_model_1988b9d517e3c16daf27a07f09e3de97_2569974802724943130.pyx", line 876, in stanfit4anon_model_1988b9d517e3c16daf27a07f09e3de97_2569974802724943130.StanFit4Model._call_sampler
  File "stanfit4anon_model_1988b9d517e3c16daf27a07f09e3de97_2569974802724943130.pyx", line 401, in stanfit4anon_model_1988b9d517e3c16daf27a07f09e3de97_2569974802724943130._call_sampler
RuntimeError: Initialization failed.

During handling of the above exception, another exception occurred:

Traceback (most recent call last):
  File "C:\Users\ckg\Envs\Prophet\lib\site-packages\grpc\_server.py", line 401, in _take_response_from_response_iterator
    return next(response_iterator), True
  File "__main__.py", line 159, in _prophet
    m.fit(dataFrame)
  File "C:\Users\ckg\Envs\Prophet\lib\site-packages\fbprophet\forecaster.py", line 840, in fit
    **kwargs
  File "C:\Users\ckg\Envs\Prophet\lib\site-packages\pystan\model.py", line 510, in optimizing
    ret, sample = fit._call_sampler(stan_args)
  File "stanfit4anon_model_1988b9d517e3c16daf27a07f09e3de97_2569974802724943130.pyx", line 876, in stanfit4anon_model_1988b9d517e3c16daf27a07f09e3de97_2569974802724943130.StanFit4Model._call_sampler
  File "stanfit4anon_model_1988b9d517e3c16daf27a07f09e3de97_2569974802724943130.pyx", line 401, in stanfit4anon_model_1988b9d517e3c16daf27a07f09e3de97_2569974802724943130._call_sampler
RuntimeError: Initialization failed.
2018-07-22 14:52:15,482 - INFO - __main__ : 252 - ExecuteFunction (functionId: 0)
2018-07-22 14:52:16,623 - ERROR - _server : 411 - Exception iterating responses: Initialization failed.
Traceback (most recent call last):
  File "C:\Users\ckg\Envs\Prophet\lib\site-packages\fbprophet\forecaster.py", line 836, in fit
    dat, init=stan_init, iter=1e4, **kwargs)
  File "C:\Users\ckg\Envs\Prophet\lib\site-packages\pystan\model.py", line 510, in optimizing
    ret, sample = fit._call_sampler(stan_args)
  File "stanfit4anon_model_1988b9d517e3c16daf27a07f09e3de97_2569974802724943130.pyx", line 876, in stanfit4anon_model_1988b9d517e3c16daf27a07f09e3de97_2569974802724943130.StanFit4Model._call_sampler
  File "stanfit4anon_model_1988b9d517e3c16daf27a07f09e3de97_2569974802724943130.pyx", line 401, in stanfit4anon_model_1988b9d517e3c16daf27a07f09e3de97_2569974802724943130._call_sampler
RuntimeError: Initialization failed.

During handling of the above exception, another exception occurred:

Traceback (most recent call last):
  File "C:\Users\ckg\Envs\Prophet\lib\site-packages\grpc\_server.py", line 401, in _take_response_from_response_iterator
    return next(response_iterator), True
  File "__main__.py", line 159, in _prophet
    m.fit(dataFrame)
  File "C:\Users\ckg\Envs\Prophet\lib\site-packages\fbprophet\forecaster.py", line 840, in fit
    **kwargs
  File "C:\Users\ckg\Envs\Prophet\lib\site-packages\pystan\model.py", line 510, in optimizing
    ret, sample = fit._call_sampler(stan_args)
  File "stanfit4anon_model_1988b9d517e3c16daf27a07f09e3de97_2569974802724943130.pyx", line 876, in stanfit4anon_model_1988b9d517e3c16daf27a07f09e3de97_2569974802724943130.StanFit4Model._call_sampler
  File "stanfit4anon_model_1988b9d517e3c16daf27a07f09e3de97_2569974802724943130.pyx", line 401, in stanfit4anon_model_1988b9d517e3c16daf27a07f09e3de97_2569974802724943130._call_sampler
RuntimeError: Initialization failed.
2018-07-22 14:54:17,185 - INFO - __main__ : 44 - Logging enabled
2018-07-22 14:54:17,195 - INFO - __main__ : 312 - *** Running server in insecure mode on port: 50066 ***
2018-07-22 14:56:05,753 - INFO - __main__ : 214 - GetCapabilities
2018-07-22 14:56:05,754 - INFO - __main__ : 237 - Adding to capabilities: Prophet(['adjustments', 'dateStamp', 'figures', 'forecastPeriod', 'forecastType', 'outliers'])
2018-07-22 14:56:31,161 - INFO - __main__ : 252 - ExecuteFunction (functionId: 0)
2018-07-22 14:56:33,260 - ERROR - _server : 411 - Exception iterating responses: Initialization failed.
Traceback (most recent call last):
  File "C:\Users\ckg\Envs\Prophet\lib\site-packages\fbprophet\forecaster.py", line 836, in fit
    dat, init=stan_init, iter=1e4, **kwargs)
  File "C:\Users\ckg\Envs\Prophet\lib\site-packages\pystan\model.py", line 510, in optimizing
    ret, sample = fit._call_sampler(stan_args)
  File "stanfit4anon_model_1988b9d517e3c16daf27a07f09e3de97_2569974802724943130.pyx", line 876, in stanfit4anon_model_1988b9d517e3c16daf27a07f09e3de97_2569974802724943130.StanFit4Model._call_sampler
  File "stanfit4anon_model_1988b9d517e3c16daf27a07f09e3de97_2569974802724943130.pyx", line 401, in stanfit4anon_model_1988b9d517e3c16daf27a07f09e3de97_2569974802724943130._call_sampler
RuntimeError: Initialization failed.

During handling of the above exception, another exception occurred:

Traceback (most recent call last):
  File "C:\Users\ckg\Envs\Prophet\lib\site-packages\grpc\_server.py", line 401, in _take_response_from_response_iterator
    return next(response_iterator), True
  File "__main__.py", line 159, in _prophet
    m.fit(dataFrame)
  File "C:\Users\ckg\Envs\Prophet\lib\site-packages\fbprophet\forecaster.py", line 840, in fit
    **kwargs
  File "C:\Users\ckg\Envs\Prophet\lib\site-packages\pystan\model.py", line 510, in optimizing
    ret, sample = fit._call_sampler(stan_args)
  File "stanfit4anon_model_1988b9d517e3c16daf27a07f09e3de97_2569974802724943130.pyx", line 876, in stanfit4anon_model_1988b9d517e3c16daf27a07f09e3de97_2569974802724943130.StanFit4Model._call_sampler
  File "stanfit4anon_model_1988b9d517e3c16daf27a07f09e3de97_2569974802724943130.pyx", line 401, in stanfit4anon_model_1988b9d517e3c16daf27a07f09e3de97_2569974802724943130._call_sampler
RuntimeError: Initialization failed.
2018-07-22 14:56:33,271 - INFO - __main__ : 252 - ExecuteFunction (functionId: 0)
2018-07-22 14:56:35,292 - ERROR - _server : 411 - Exception iterating responses: Initialization failed.
Traceback (most recent call last):
  File "C:\Users\ckg\Envs\Prophet\lib\site-packages\fbprophet\forecaster.py", line 836, in fit
    dat, init=stan_init, iter=1e4, **kwargs)
  File "C:\Users\ckg\Envs\Prophet\lib\site-packages\pystan\model.py", line 510, in optimizing
    ret, sample = fit._call_sampler(stan_args)
  File "stanfit4anon_model_1988b9d517e3c16daf27a07f09e3de97_2569974802724943130.pyx", line 876, in stanfit4anon_model_1988b9d517e3c16daf27a07f09e3de97_2569974802724943130.StanFit4Model._call_sampler
  File "stanfit4anon_model_1988b9d517e3c16daf27a07f09e3de97_2569974802724943130.pyx", line 401, in stanfit4anon_model_1988b9d517e3c16daf27a07f09e3de97_2569974802724943130._call_sampler
RuntimeError: Initialization failed.

During handling of the above exception, another exception occurred:

Traceback (most recent call last):
  File "C:\Users\ckg\Envs\Prophet\lib\site-packages\grpc\_server.py", line 401, in _take_response_from_response_iterator
    return next(response_iterator), True
  File "__main__.py", line 159, in _prophet
    m.fit(dataFrame)
  File "C:\Users\ckg\Envs\Prophet\lib\site-packages\fbprophet\forecaster.py", line 840, in fit
    **kwargs
  File "C:\Users\ckg\Envs\Prophet\lib\site-packages\pystan\model.py", line 510, in optimizing
    ret, sample = fit._call_sampler(stan_args)
  File "stanfit4anon_model_1988b9d517e3c16daf27a07f09e3de97_2569974802724943130.pyx", line 876, in stanfit4anon_model_1988b9d517e3c16daf27a07f09e3de97_2569974802724943130.StanFit4Model._call_sampler
  File "stanfit4anon_model_1988b9d517e3c16daf27a07f09e3de97_2569974802724943130.pyx", line 401, in stanfit4anon_model_1988b9d517e3c16daf27a07f09e3de97_2569974802724943130._call_sampler
RuntimeError: Initialization failed.
2018-07-22 14:57:26,527 - INFO - __main__ : 252 - ExecuteFunction (functionId: 0)
2018-07-22 14:57:28,404 - ERROR - _server : 411 - Exception iterating responses: Initialization failed.
Traceback (most recent call last):
  File "C:\Users\ckg\Envs\Prophet\lib\site-packages\fbprophet\forecaster.py", line 836, in fit
    dat, init=stan_init, iter=1e4, **kwargs)
  File "C:\Users\ckg\Envs\Prophet\lib\site-packages\pystan\model.py", line 510, in optimizing
    ret, sample = fit._call_sampler(stan_args)
  File "stanfit4anon_model_1988b9d517e3c16daf27a07f09e3de97_2569974802724943130.pyx", line 876, in stanfit4anon_model_1988b9d517e3c16daf27a07f09e3de97_2569974802724943130.StanFit4Model._call_sampler
  File "stanfit4anon_model_1988b9d517e3c16daf27a07f09e3de97_2569974802724943130.pyx", line 401, in stanfit4anon_model_1988b9d517e3c16daf27a07f09e3de97_2569974802724943130._call_sampler
RuntimeError: Initialization failed.

During handling of the above exception, another exception occurred:

Traceback (most recent call last):
  File "C:\Users\ckg\Envs\Prophet\lib\site-packages\grpc\_server.py", line 401, in _take_response_from_response_iterator
    return next(response_iterator), True
  File "__main__.py", line 159, in _prophet
    m.fit(dataFrame)
  File "C:\Users\ckg\Envs\Prophet\lib\site-packages\fbprophet\forecaster.py", line 840, in fit
    **kwargs
  File "C:\Users\ckg\Envs\Prophet\lib\site-packages\pystan\model.py", line 510, in optimizing
    ret, sample = fit._call_sampler(stan_args)
  File "stanfit4anon_model_1988b9d517e3c16daf27a07f09e3de97_2569974802724943130.pyx", line 876, in stanfit4anon_model_1988b9d517e3c16daf27a07f09e3de97_2569974802724943130.StanFit4Model._call_sampler
  File "stanfit4anon_model_1988b9d517e3c16daf27a07f09e3de97_2569974802724943130.pyx", line 401, in stanfit4anon_model_1988b9d517e3c16daf27a07f09e3de97_2569974802724943130._call_sampler
RuntimeError: Initialization failed.
2018-07-22 15:01:03,555 - INFO - __main__ : 44 - Logging enabled
2018-07-22 15:01:03,564 - INFO - __main__ : 312 - *** Running server in insecure mode on port: 50066 ***
2018-07-22 15:01:13,135 - INFO - __main__ : 252 - ExecuteFunction (functionId: 0)
2018-07-22 15:01:16,302 - ERROR - _server : 411 - Exception iterating responses: Initialization failed.
Traceback (most recent call last):
  File "C:\Users\ckg\Envs\Prophet\lib\site-packages\fbprophet\forecaster.py", line 836, in fit
    dat, init=stan_init, iter=1e4, **kwargs)
  File "C:\Users\ckg\Envs\Prophet\lib\site-packages\pystan\model.py", line 510, in optimizing
    ret, sample = fit._call_sampler(stan_args)
  File "stanfit4anon_model_1988b9d517e3c16daf27a07f09e3de97_2569974802724943130.pyx", line 876, in stanfit4anon_model_1988b9d517e3c16daf27a07f09e3de97_2569974802724943130.StanFit4Model._call_sampler
  File "stanfit4anon_model_1988b9d517e3c16daf27a07f09e3de97_2569974802724943130.pyx", line 401, in stanfit4anon_model_1988b9d517e3c16daf27a07f09e3de97_2569974802724943130._call_sampler
RuntimeError: Initialization failed.

During handling of the above exception, another exception occurred:

Traceback (most recent call last):
  File "C:\Users\ckg\Envs\Prophet\lib\site-packages\grpc\_server.py", line 401, in _take_response_from_response_iterator
    return next(response_iterator), True
  File "__main__.py", line 159, in _prophet
    m.fit(dataFrame)
  File "C:\Users\ckg\Envs\Prophet\lib\site-packages\fbprophet\forecaster.py", line 840, in fit
    **kwargs
  File "C:\Users\ckg\Envs\Prophet\lib\site-packages\pystan\model.py", line 510, in optimizing
    ret, sample = fit._call_sampler(stan_args)
  File "stanfit4anon_model_1988b9d517e3c16daf27a07f09e3de97_2569974802724943130.pyx", line 876, in stanfit4anon_model_1988b9d517e3c16daf27a07f09e3de97_2569974802724943130.StanFit4Model._call_sampler
  File "stanfit4anon_model_1988b9d517e3c16daf27a07f09e3de97_2569974802724943130.pyx", line 401, in stanfit4anon_model_1988b9d517e3c16daf27a07f09e3de97_2569974802724943130._call_sampler
RuntimeError: Initialization failed.
2018-07-22 15:01:16,334 - INFO - __main__ : 252 - ExecuteFunction (functionId: 0)
2018-07-22 15:01:21,930 - ERROR - _server : 411 - Exception iterating responses: Initialization failed.
Traceback (most recent call last):
  File "C:\Users\ckg\Envs\Prophet\lib\site-packages\fbprophet\forecaster.py", line 836, in fit
    dat, init=stan_init, iter=1e4, **kwargs)
  File "C:\Users\ckg\Envs\Prophet\lib\site-packages\pystan\model.py", line 510, in optimizing
    ret, sample = fit._call_sampler(stan_args)
  File "stanfit4anon_model_1988b9d517e3c16daf27a07f09e3de97_2569974802724943130.pyx", line 876, in stanfit4anon_model_1988b9d517e3c16daf27a07f09e3de97_2569974802724943130.StanFit4Model._call_sampler
  File "stanfit4anon_model_1988b9d517e3c16daf27a07f09e3de97_2569974802724943130.pyx", line 401, in stanfit4anon_model_1988b9d517e3c16daf27a07f09e3de97_2569974802724943130._call_sampler
RuntimeError: Initialization failed.

During handling of the above exception, another exception occurred:

Traceback (most recent call last):
  File "C:\Users\ckg\Envs\Prophet\lib\site-packages\grpc\_server.py", line 401, in _take_response_from_response_iterator
    return next(response_iterator), True
  File "__main__.py", line 159, in _prophet
    m.fit(dataFrame)
  File "C:\Users\ckg\Envs\Prophet\lib\site-packages\fbprophet\forecaster.py", line 840, in fit
    **kwargs
  File "C:\Users\ckg\Envs\Prophet\lib\site-packages\pystan\model.py", line 510, in optimizing
    ret, sample = fit._call_sampler(stan_args)
  File "stanfit4anon_model_1988b9d517e3c16daf27a07f09e3de97_2569974802724943130.pyx", line 876, in stanfit4anon_model_1988b9d517e3c16daf27a07f09e3de97_2569974802724943130.StanFit4Model._call_sampler
  File "stanfit4anon_model_1988b9d517e3c16daf27a07f09e3de97_2569974802724943130.pyx", line 401, in stanfit4anon_model_1988b9d517e3c16daf27a07f09e3de97_2569974802724943130._call_sampler
RuntimeError: Initialization failed.
2018-07-22 15:01:54,246 - INFO - __main__ : 214 - GetCapabilities
2018-07-22 15:01:54,256 - INFO - __main__ : 237 - Adding to capabilities: Prophet(['adjustments', 'dateStamp', 'figures', 'forecastPeriod', 'forecastType', 'outliers'])
2018-07-22 15:01:58,384 - INFO - __main__ : 252 - ExecuteFunction (functionId: 0)
2018-07-22 15:02:01,455 - ERROR - _server : 411 - Exception iterating responses: Expecting value: line 1 column 1 (char 0)
Traceback (most recent call last):
  File "C:\Users\ckg\Envs\Prophet\lib\site-packages\grpc\_server.py", line 401, in _take_response_from_response_iterator
    return next(response_iterator), True
  File "__main__.py", line 171, in _prophet
    adjJson = json.loads(adjustments)
  File "c:\users\ckg\appdata\local\continuum\anaconda3\Lib\json\__init__.py", line 354, in loads
    return _default_decoder.decode(s)
  File "c:\users\ckg\appdata\local\continuum\anaconda3\Lib\json\decoder.py", line 339, in decode
    obj, end = self.raw_decode(s, idx=_w(s, 0).end())
  File "c:\users\ckg\appdata\local\continuum\anaconda3\Lib\json\decoder.py", line 357, in raw_decode
    raise JSONDecodeError("Expecting value", s, err.value) from None
json.decoder.JSONDecodeError: Expecting value: line 1 column 1 (char 0)
2018-07-22 15:02:01,482 - INFO - __main__ : 252 - ExecuteFunction (functionId: 0)
2018-07-22 15:02:06,264 - ERROR - _server : 411 - Exception iterating responses: Expecting value: line 1 column 1 (char 0)
Traceback (most recent call last):
  File "C:\Users\ckg\Envs\Prophet\lib\site-packages\grpc\_server.py", line 401, in _take_response_from_response_iterator
    return next(response_iterator), True
  File "__main__.py", line 171, in _prophet
    adjJson = json.loads(adjustments)
  File "c:\users\ckg\appdata\local\continuum\anaconda3\Lib\json\__init__.py", line 354, in loads
    return _default_decoder.decode(s)
  File "c:\users\ckg\appdata\local\continuum\anaconda3\Lib\json\decoder.py", line 339, in decode
    obj, end = self.raw_decode(s, idx=_w(s, 0).end())
  File "c:\users\ckg\appdata\local\continuum\anaconda3\Lib\json\decoder.py", line 357, in raw_decode
    raise JSONDecodeError("Expecting value", s, err.value) from None
json.decoder.JSONDecodeError: Expecting value: line 1 column 1 (char 0)
2018-07-22 15:04:24,843 - INFO - __main__ : 252 - ExecuteFunction (functionId: 0)
2018-07-22 15:04:25,047 - ERROR - _server : 411 - Exception iterating responses: Dataframe has less than 2 non-NaN rows.
Traceback (most recent call last):
  File "C:\Users\ckg\Envs\Prophet\lib\site-packages\grpc\_server.py", line 401, in _take_response_from_response_iterator
    return next(response_iterator), True
  File "__main__.py", line 159, in _prophet
    m.fit(dataFrame)
  File "C:\Users\ckg\Envs\Prophet\lib\site-packages\fbprophet\forecaster.py", line 775, in fit
    raise ValueError('Dataframe has less than 2 non-NaN rows.')
ValueError: Dataframe has less than 2 non-NaN rows.
2018-07-22 15:04:51,824 - INFO - __main__ : 44 - Logging enabled
2018-07-22 15:04:51,837 - INFO - __main__ : 312 - *** Running server in insecure mode on port: 50066 ***
2018-07-22 15:05:02,467 - INFO - __main__ : 214 - GetCapabilities
2018-07-22 15:05:02,474 - INFO - __main__ : 237 - Adding to capabilities: Prophet(['adjustments', 'dateStamp', 'figures', 'forecastPeriod', 'forecastType', 'outliers'])
2018-07-22 15:05:43,523 - INFO - __main__ : 252 - ExecuteFunction (functionId: 0)
2018-07-22 15:05:43,743 - ERROR - _server : 411 - Exception iterating responses: Dataframe has less than 2 non-NaN rows.
Traceback (most recent call last):
  File "C:\Users\ckg\Envs\Prophet\lib\site-packages\grpc\_server.py", line 401, in _take_response_from_response_iterator
    return next(response_iterator), True
  File "__main__.py", line 159, in _prophet
    m.fit(dataFrame)
  File "C:\Users\ckg\Envs\Prophet\lib\site-packages\fbprophet\forecaster.py", line 775, in fit
    raise ValueError('Dataframe has less than 2 non-NaN rows.')
ValueError: Dataframe has less than 2 non-NaN rows.
2018-07-22 15:08:26,408 - INFO - __main__ : 44 - Logging enabled
2018-07-22 15:08:26,418 - INFO - __main__ : 312 - *** Running server in insecure mode on port: 50066 ***
2018-07-22 15:10:33,329 - INFO - __main__ : 252 - ExecuteFunction (functionId: 0)
2018-07-22 15:10:36,541 - ERROR - _server : 411 - Exception iterating responses: string indices must be integers
Traceback (most recent call last):
  File "C:\Users\ckg\Envs\Prophet\lib\site-packages\grpc\_server.py", line 401, in _take_response_from_response_iterator
    return next(response_iterator), True
  File "__main__.py", line 174, in _prophet
    if item["firstField"] == row["ds"]:
TypeError: string indices must be integers
2018-07-22 15:14:21,940 - INFO - __main__ : 44 - Logging enabled
2018-07-22 15:14:21,950 - INFO - __main__ : 310 - *** Running server in insecure mode on port: 50066 ***
2018-07-22 15:14:35,234 - INFO - __main__ : 250 - ExecuteFunction (functionId: 0)
2018-07-22 15:14:38,333 - ERROR - _server : 411 - Exception iterating responses: too many values to unpack (expected 2)
Traceback (most recent call last):
  File "C:\Users\ckg\Envs\Prophet\lib\site-packages\grpc\_server.py", line 401, in _take_response_from_response_iterator
    return next(response_iterator), True
  File "__main__.py", line 169, in _prophet
    for index, row in forecast:
ValueError: too many values to unpack (expected 2)
2018-07-22 15:19:48,926 - INFO - __main__ : 44 - Logging enabled
2018-07-22 15:19:48,936 - INFO - __main__ : 308 - *** Running server in insecure mode on port: 50066 ***
2018-07-22 15:19:58,462 - INFO - __main__ : 248 - ExecuteFunction (functionId: 0)
2018-07-22 15:20:02,042 - ERROR - _server : 411 - Exception iterating responses: too many values to unpack (expected 2)
Traceback (most recent call last):
  File "C:\Users\ckg\Envs\Prophet\lib\site-packages\grpc\_server.py", line 401, in _take_response_from_response_iterator
    return next(response_iterator), True
  File "__main__.py", line 169, in _prophet
    for index, row in forecast:
ValueError: too many values to unpack (expected 2)
2018-07-22 15:21:30,131 - INFO - __main__ : 44 - Logging enabled
2018-07-22 15:21:30,142 - INFO - __main__ : 310 - *** Running server in insecure mode on port: 50066 ***
2018-07-22 15:21:44,730 - INFO - __main__ : 250 - ExecuteFunction (functionId: 0)
2018-07-22 15:21:47,835 - ERROR - _server : 411 - Exception iterating responses: 'ds'
Traceback (most recent call last):
  File "pandas\_libs\index.pyx", line 162, in pandas._libs.index.IndexEngine.get_loc
  File "pandas\_libs\hashtable_class_helper.pxi", line 958, in pandas._libs.hashtable.Int64HashTable.get_item
TypeError: an integer is required

During handling of the above exception, another exception occurred:

Traceback (most recent call last):
  File "C:\Users\ckg\Envs\Prophet\lib\site-packages\grpc\_server.py", line 401, in _take_response_from_response_iterator
    return next(response_iterator), True
  File "__main__.py", line 172, in _prophet
    if item["firstField"] == row["ds"]:
  File "C:\Users\ckg\Envs\Prophet\lib\site-packages\pandas\core\series.py", line 766, in __getitem__
    result = self.index.get_value(self, key)
  File "C:\Users\ckg\Envs\Prophet\lib\site-packages\pandas\core\indexes\base.py", line 3103, in get_value
    tz=getattr(series.dtype, 'tz', None))
  File "pandas\_libs\index.pyx", line 106, in pandas._libs.index.IndexEngine.get_value
  File "pandas\_libs\index.pyx", line 114, in pandas._libs.index.IndexEngine.get_value
  File "pandas\_libs\index.pyx", line 164, in pandas._libs.index.IndexEngine.get_loc
KeyError: 'ds'
2018-07-22 15:25:34,755 - INFO - __main__ : 44 - Logging enabled
2018-07-22 15:25:34,765 - INFO - __main__ : 310 - *** Running server in insecure mode on port: 50066 ***
2018-07-22 15:25:42,252 - INFO - __main__ : 250 - ExecuteFunction (functionId: 0)
2018-07-22 15:25:45,224 - ERROR - _server : 411 - Exception iterating responses: The truth value of a Series is ambiguous. Use a.empty, a.bool(), a.item(), a.any() or a.all().
Traceback (most recent call last):
  File "C:\Users\ckg\Envs\Prophet\lib\site-packages\grpc\_server.py", line 401, in _take_response_from_response_iterator
    return next(response_iterator), True
  File "__main__.py", line 172, in _prophet
    if item["firstField"] == row:
  File "C:\Users\ckg\Envs\Prophet\lib\site-packages\pandas\core\generic.py", line 1573, in __nonzero__
    .format(self.__class__.__name__))
ValueError: The truth value of a Series is ambiguous. Use a.empty, a.bool(), a.item(), a.any() or a.all().
2018-07-22 15:28:00,231 - INFO - __main__ : 44 - Logging enabled
2018-07-22 15:28:00,241 - INFO - __main__ : 310 - *** Running server in insecure mode on port: 50066 ***
2018-07-22 15:28:06,663 - INFO - __main__ : 250 - ExecuteFunction (functionId: 0)
2018-07-22 15:28:09,803 - ERROR - _server : 411 - Exception iterating responses: The truth value of a Series is ambiguous. Use a.empty, a.bool(), a.item(), a.any() or a.all().
Traceback (most recent call last):
  File "C:\Users\ckg\Envs\Prophet\lib\site-packages\grpc\_server.py", line 401, in _take_response_from_response_iterator
    return next(response_iterator), True
  File "__main__.py", line 172, in _prophet
    if item["firstField"] == row:
  File "C:\Users\ckg\Envs\Prophet\lib\site-packages\pandas\core\generic.py", line 1573, in __nonzero__
    .format(self.__class__.__name__))
ValueError: The truth value of a Series is ambiguous. Use a.empty, a.bool(), a.item(), a.any() or a.all().
2018-07-22 15:30:15,623 - INFO - __main__ : 44 - Logging enabled
2018-07-22 15:30:15,633 - INFO - __main__ : 309 - *** Running server in insecure mode on port: 50066 ***
2018-07-22 15:30:23,709 - INFO - __main__ : 249 - ExecuteFunction (functionId: 0)
2018-07-22 15:33:06,562 - INFO - __main__ : 249 - ExecuteFunction (functionId: 0)
2018-07-22 15:33:37,996 - INFO - __main__ : 249 - ExecuteFunction (functionId: 0)
