2018-07-03 08:18:31,868 - INFO - __main__ : 43 - Logging enabled
2018-07-03 08:18:31,962 - INFO - __main__ : 299 - *** Running server in insecure mode on port: 50066 ***
2018-07-03 08:23:19,604 - INFO - __main__ : 201 - GetCapabilities
2018-07-03 08:23:19,618 - INFO - __main__ : 224 - Adding to capabilities: Prophet(['dateStamp', 'figures', 'forecastPeriod', 'forecastType', 'outliers'])
2018-07-03 08:25:46,994 - INFO - __main__ : 239 - ExecuteFunction (functionId: 0)
2018-07-03 08:25:46,998 - ERROR - _server : 411 - Exception iterating responses: year 39346 is out of range
Traceback (most recent call last):
  File "C:\Users\ckg\Envs\Prophet\lib\site-packages\grpc\_server.py", line 401, in _take_response_from_response_iterator
    return next(response_iterator), True
  File "__main__.py", line 104, in _prophet
    pythonDate = datetime.fromordinal(datetime(1900, 1, 1).toordinal() + int(dateStamps) - 2)
ValueError: year 39346 is out of range
2018-07-03 08:25:50,451 - INFO - __main__ : 239 - ExecuteFunction (functionId: 0)
2018-07-03 08:25:50,454 - ERROR - _server : 411 - Exception iterating responses: year 39346 is out of range
Traceback (most recent call last):
  File "C:\Users\ckg\Envs\Prophet\lib\site-packages\grpc\_server.py", line 401, in _take_response_from_response_iterator
    return next(response_iterator), True
  File "__main__.py", line 104, in _prophet
    pythonDate = datetime.fromordinal(datetime(1900, 1, 1).toordinal() + int(dateStamps) - 2)
ValueError: year 39346 is out of range
2018-07-03 08:32:43,176 - INFO - __main__ : 43 - Logging enabled
2018-07-03 08:32:43,228 - INFO - __main__ : 299 - *** Running server in insecure mode on port: 50066 ***
2018-07-03 08:32:50,850 - INFO - __main__ : 239 - ExecuteFunction (functionId: 0)
2018-07-03 08:32:50,852 - ERROR - _server : 411 - Exception iterating responses: year 39346 is out of range
Traceback (most recent call last):
  File "C:\Users\ckg\Envs\Prophet\lib\site-packages\grpc\_server.py", line 401, in _take_response_from_response_iterator
    return next(response_iterator), True
  File "__main__.py", line 104, in _prophet
    pythonDate = datetime.fromordinal(datetime(1900, 1, 1).toordinal() + int(dateStamps) - 2)
ValueError: year 39346 is out of range
2018-07-03 08:33:02,365 - INFO - __main__ : 239 - ExecuteFunction (functionId: 0)
2018-07-03 08:33:02,367 - ERROR - _server : 411 - Exception iterating responses: year 39346 is out of range
Traceback (most recent call last):
  File "C:\Users\ckg\Envs\Prophet\lib\site-packages\grpc\_server.py", line 401, in _take_response_from_response_iterator
    return next(response_iterator), True
  File "__main__.py", line 104, in _prophet
    pythonDate = datetime.fromordinal(datetime(1900, 1, 1).toordinal() + int(dateStamps) - 2)
ValueError: year 39346 is out of range
2018-07-03 08:48:48,257 - INFO - __main__ : 239 - ExecuteFunction (functionId: 0)
2018-07-03 08:48:48,258 - ERROR - _server : 411 - Exception iterating responses: year 39346 is out of range
Traceback (most recent call last):
  File "C:\Users\ckg\Envs\Prophet\lib\site-packages\grpc\_server.py", line 401, in _take_response_from_response_iterator
    return next(response_iterator), True
  File "__main__.py", line 104, in _prophet
    pythonDate = datetime.fromordinal(datetime(1900, 1, 1).toordinal() + int(dateStamps) - 2)
ValueError: year 39346 is out of range
2018-07-03 09:04:13,865 - INFO - __main__ : 239 - ExecuteFunction (functionId: 0)
2018-07-03 09:04:13,867 - ERROR - _server : 411 - Exception iterating responses: year 39346 is out of range
Traceback (most recent call last):
  File "C:\Users\ckg\Envs\Prophet\lib\site-packages\grpc\_server.py", line 401, in _take_response_from_response_iterator
    return next(response_iterator), True
  File "__main__.py", line 104, in _prophet
    pythonDate = datetime.fromordinal(datetime(1900, 1, 1).toordinal() + int(dateStamps) - 2)
ValueError: year 39346 is out of range
2018-07-03 09:07:57,184 - INFO - __main__ : 239 - ExecuteFunction (functionId: 0)
2018-07-03 09:07:57,185 - ERROR - _server : 411 - Exception iterating responses: year 39346 is out of range
Traceback (most recent call last):
  File "C:\Users\ckg\Envs\Prophet\lib\site-packages\grpc\_server.py", line 401, in _take_response_from_response_iterator
    return next(response_iterator), True
  File "__main__.py", line 104, in _prophet
    pythonDate = datetime.fromordinal(datetime(1900, 1, 1).toordinal() + int(dateStamps) - 2)
ValueError: year 39346 is out of range
